Workbook

Sheet Summary SI, Rental & Subcon
A1: Amaala Project Manpower 20/12/2025 | AE1: Total
A2: Saudi Icon & Rental
A3: Compnay :- | B3: Saudi Icon | H3: Deemah Stone | J3: Hi-Tech | K3: Sultan | M3: Romeo | O3: Rekab | P3: Medtel | S3: Wakil | T3: BOLD | W3: Tarzou | X3: Juri | AA3: Abu Umar | AB3: C&C
A4: Position | B4: Zone 08 Office | C4: Villas | D4: B2 | E4: B3 | F4: LaydownStore | G4: GRG-Laydwon | H4: B2 | I4: Villa | J4: B3 | K4: B3 | L4: Villa | M4: B3 | N4: B2 | O4: Villa | P4: B2 | Q4: Villa | R4: B3 | S4: Villa | T4: Villa | U4: B2 | V4: B3 | W4: B3 | X4: B3 | Y4: B2 | Z4: Villa | AA4: B3 | AB4: B2 | AC4: Villa | AD4: B3
A5: Project Director | B5: 1 | C5: - | D5: - | E5: - | F5: - | G5: - | H5: - | I5: - | J5: - | K5: - | L5: - | M5: - | N5: - | O5: - | P5: - | Q5: - | R5: - | S5: - | T5: - | U5: - | V5: - | W5: - | X5: - | Y5: - | Z5: - | AA5: - | AB5: - | AC5: - | AD5: - | AE5: =SUM(B5:AD5) -> 1
A6: Asst. Project Director | B6: 1 | C6: - | D6: - | E6: - | F6: - | G6: - | H6: - | I6: - | J6: - | K6: - | L6: - | M6: - | N6: - | O6: - | P6: - | Q6: - | R6: - | S6: - | T6: - | U6: - | V6: - | W6: - | X6: - | Y6: - | Z6: - | AA6: - | AB6: - | AC6: - | AD6: - | AE6: =SUM(B6:AD6) -> 1
A7: Construction Manager | B7: 1 | C7: - | D7: - | E7: - | F7: - | G7: - | H7: - | I7: - | J7: - | K7: - | L7: - | M7: - | N7: - | S7: - | T7: - | U7: - | AE7: =SUM(B7:AD7) -> 1
A8: Project Manager | B8: 1 | C8: - | D8: - | E8: - | F8: - | G8: - | H8: - | I8: - | J8: - | K8: - | L8: - | M8: - | N8: - | O8: - | P8: - | Q8: - | R8: - | S8: - | T8: - | U8: - | V8: - | W8: - | X8: - | Y8: - | Z8: - | AA8: - | AB8: - | AC8: - | AD8: - | AE8: =SUM(B8:AD8) -> 1
A9: Safety Manager | B9: 1 | C9: - | D9: - | E9: - | F9: - | G9: - | H9: - | I9: - | J9: - | K9: - | L9: - | M9: - | N9: - | O9: - | P9: - | Q9: - | R9: - | S9: - | T9: - | U9: - | V9: - | W9: - | X9: - | Y9: - | Z9: - | AA9: - | AB9: - | AC9: - | AD9: - | AE9: =SUM(B9:AD9) -> 1
A10: Q Surveyor Engineer | B10: 1 | C10: - | D10: - | E10: - | F10: - | G10: - | H10: - | I10: - | J10: - | K10: - | L10: - | M10: - | N10: - | O10: - | P10: - | Q10: - | R10: - | S10: - | T10: - | U10: - | V10: - | W10: - | X10: - | Y10: - | Z10: - | AA10: - | AB10: - | AC10: - | AD10: - | AE10: =SUM(B10:AD10) -> 1
A11: QC Manager | B11: 1 | C11: - | D11: - | E11: - | F11: - | G11: - | H11: - | I11: - | J11: - | K11: - | L11: - | M11: - | N11: - | O11: - | P11: - | Q11: - | R11: - | S11: - | T11: - | U11: - | V11: - | W11: - | X11: - | Y11: - | Z11: - | AA11: - | AB11: - | AC11: - | AD11: - | AE11: =SUM(B11:AD11) -> 1
A12: Planning Engineer | B12: 1 | C12: - | D12: - | E12: - | F12: - | G12: - | H12: - | I12: - | J12: - | K12: - | L12: - | M12: - | N12: - | O12: - | P12: - | Q12: - | R12: - | S12: - | T12: - | U12: - | V12: - | W12: - | X12: - | Y12: - | Z12: - | AA12: - | AB12: - | AC12: - | AD12: - | AE12: =SUM(B12:AD12) -> 1
A13: Admin Assistant | B13: 1 | C13: - | D13: - | E13: - | F13: - | G13: - | H13: - | I13: - | J13: - | K13: - | L13: - | M13: - | N13: - | O13: - | P13: - | Q13: - | R13: - | S13: - | T13: - | U13: - | V13: - | W13: - | X13: - | Y13: - | Z13: - | AA13: - | AE13: =SUM(B13:AD13) -> 1
A14: Environmental Engineer | B14: 2 | C14: - | D14: - | E14: - | F14: - | G14: - | H14: - | I14: - | J14: - | K14: - | L14: - | M14: - | N14: - | O14: - | P14: - | Q14: - | R14: - | S14: - | T14: - | U14: - | V14: - | W14: - | X14: - | Y14: - | Z14: - | AA14: - | AB14: - | AC14: - | AD14: - | AE14: =SUM(B14:AD14) -> 2
A15: QC Enginner | B15: 2 | C15: - | D15: - | E15: - | F15: - | G15: - | H15: - | I15: - | J15: - | K15: - | L15: - | M15: - | N15: - | O15: - | P15: - | Q15: - | R15: - | S15: - | T15: - | U15: - | V15: - | W15: - | X15: - | Y15: - | Z15: - | AA15: - | AB15: - | AC15: - | AD15: - | AE15: =SUM(B15:AD15) -> 2
A16: Site Engineer | B16: 2 | C16: 3 | D16: 2 | E16: 6 | F16: - | G16: - | H16: - | I16: - | J16: - | K16: - | L16: - | M16: - | N16: - | O16: - | P16: - | Q16: - | R16: - | S16: - | T16: - | U16: - | V16: - | W16: - | X16: - | Y16: - | Z16: - | AA16: - | AB16: - | AC16: - | AD16: - | AE16: =SUM(B16:AD16) -> 13
A17: Logistics Officer | B17: - | C17: - | D17: - | E17: - | F17: 1 | G17: - | H17: - | I17: - | J17: - | K17: - | L17: - | M17: - | N17: - | O17: - | P17: - | Q17: - | R17: - | S17: - | T17: - | U17: - | V17: - | W17: - | X17: - | Y17: - | Z17: - | AA17: - | AB17: - | AC17: - | AD17: - | AE17: =SUM(B17:AD17) -> 1
A18: Document Controller | B18: 1 | C18: - | D18: - | E18: - | F18: - | G18: - | I18: - | J18: - | K18: - | L18: - | M18: - | N18: - | O18: - | P18: - | Q18: - | R18: - | S18: - | T18: - | U18: - | V18: - | W18: - | X18: - | Y18: - | Z18: - | AA18: - | AB18: - | AC18: - | AD18: - | AE18: =SUM(B18:AD18) -> 1
A19: Timekeeper | B19: 2 | C19: - | D19: - | E19: - | F19: - | G19: - | H19: - | I19: - | J19: - | K19: - | L19: - | M19: - | N19: - | O19: - | P19: - | Q19: - | R19: - | S19: - | T19: - | U19: - | V19: - | W19: - | X19: - | Y19: - | Z19: - | AA19: - | AB19: - | AC19: - | AD19: - | AE19: =SUM(B19:AD19) -> 2
A20: Surveyor | B20: - | C20: - | D20: - | E20: 1 | F20: - | G20: - | H20: - | I20: - | J20: - | K20: - | L20: - | M20: - | N20: - | O20: - | P20: - | Q20: - | R20: - | S20: - | T20: - | U20: - | V20: - | W20: - | X20: - | Y20: - | Z20: - | AA20: - | AB20: - | AC20: - | AD20: - | AE20: =SUM(B20:AD20) -> 1
A21: Safety Officer | B21: - | C21: 3 | D21: 1 | E21: 5 | F21: - | G21: - | H21: - | I21: - | J21: - | K21: - | L21: - | M21: - | N21: - | O21: - | P21: - | Q21: - | R21: - | S21: - | T21: - | U21: - | V21: - | W21: - | X21: - | Y21: - | Z21: - | AA21: - | AB21: - | AC21: - | AD21: - | AE21: =SUM(B21:AD21) -> 9
A22: Sacfolder inspector | B22: - | C22: 1 | D22: - | E22: 2 | F22: - | G22: - | H22: - | I22: - | J22: - | K22: - | L22: - | M22: - | N22: - | O22: - | P22: - | Q22: - | R22: - | S22: - | T22: - | U22: - | V22: - | W22: - | X22: - | Y22: - | Z22: - | AA22: - | AB22: - | AC22: - | AD22: - | AE22: =SUM(B22:AD22) -> 3
A23: Site Supervisor | B23: - | C23: 2 | D23: 1 | E23: 3 | F23: - | G23: - | H23: - | I23: - | J23: - | K23: - | L23: - | M23: - | N23: - | O23: - | P23: - | Q23: - | R23: - | S23: - | T23: - | U23: - | V23: 1 | W23: - | X23: - | Y23: - | Z23: - | AA23: - | AB23: - | AC23: - | AD23: - | AE23: =SUM(B23:AD23) -> 7
A24: Storekeeper | B24: - | C24: - | D24: - | E24: - | F24: 1 | G24: - | H24: - | I24: - | J24: - | K24: - | L24: - | M24: - | N24: - | O24: - | P24: - | Q24: - | R24: - | S24: - | T24: - | U24: - | V24: - | W24: - | X24: - | Y24: - | Z24: - | AA24: - | AB24: - | AC24: - | AD24: - | AE24: =SUM(B24:AD24) -> 1
A25: General Foreman | B25: - | C25: 3 | D25: 1 | E25: 3 | F25: - | G25: - | H25: - | I25: - | J25: - | K25: - | L25: - | M25: - | N25: - | O25: - | P25: - | Q25: 2 | R25: - | S25: - | T25: - | U25: - | V25: - | W25: - | X25: - | Y25: - | Z25: - | AA25: - | AB25: - | AC25: - | AD25: - | AE25: =SUM(B25:AD25) -> 9
A26: Painter Forman | B26: - | C26: - | D26: 1 | E26: - | F26: - | G26: - | H26: - | I26: - | J26: - | K26: - | L26: - | M26: - | N26: - | O26: - | P26: - | Q26: - | R26: - | S26: - | T26: - | U26: - | V26: - | W26: - | X26: - | Y26: - | Z26: - | AA26: - | AB26: - | AC26: - | AD26: - | AE26: =SUM(B26:AD26) -> 1
A27: Carpenter Forman | B27: - | C27: 1 | D27: - | E27: - | F27: - | G27: - | H27: - | I27: - | J27: - | K27: - | L27: - | M27: - | N27: - | O27: - | P27: - | Q27: - | R27: - | S27: - | T27: - | U27: - | V27: - | W27: - | X27: - | Y27: - | Z27: - | AA27: - | AB27: - | AC27: - | AD27: - | AE27: 1
A28: Foreman Carpenter | B28: - | C28: - | D28: - | E28: 1 | F28: - | G28: - | H28: - | I28: - | J28: - | K28: - | L28: - | M28: - | N28: - | O28: - | P28: - | Q28: - | R28: - | S28: - | T28: - | U28: - | V28: - | W28: - | X28: - | Y28: - | Z28: - | AA28: - | AB28: - | AC28: - | AD28: - | AE28: =SUM(B28:AD28) -> 1
A29: Gypsum Installer - Team Leader | B29: - | C29: 1 | D29: - | E29: 4 | F29: - | G29: - | H29: - | I29: - | J29: - | K29: - | L29: - | M29: - | N29: - | O29: - | P29: - | Q29: - | R29: - | S29: - | T29: - | U29: - | V29: - | W29: - | X29: - | Y29: - | Z29: - | AA29: - | AB29: - | AC29: - | AD29: - | AE29: =SUM(B29:AD29) -> 5
A30: Mason - Tiler Tiler Leader | B30: - | C30: 1 | D30: 1 | E30: 1 | F30: - | G30: - | H30: - | J30: - | K30: - | L30: - | M30: - | N30: - | O30: - | P30: - | Q30: - | R30: - | S30: - | T30: - | U30: - | V30: - | W30: - | X30: - | Y30: - | Z30: - | AA30: - | AB30: - | AC30: - | AD30: - | AE30: =SUM(B30:AD30) -> 3
A31: Gypsum Installer | B31: - | C31: 26 | D31: 4 | E31: 19 | F31: - | G31: 4 | H31: - | I31: 0 | J31: - | K31: 0 | L31: 17 | M31: - | N31: - | O31: 0 | P31: 1 | Q31: 29 | R31: 10 | S31: 0 | T31: 0 | U31: 0 | V31: 23 | W31: - | X31: - | Y31: - | Z31: - | AA31: - | AB31: - | AC31: - | AD31: - | AE31: =SUM(B31:AD31) -> 133
A32: Mason - Tiler/Mason | B32: - | C32: 6 | D32: 24 | E32: 18 | F32: 1 | G32: - | H32: - | I32: 16 | J32: - | K32: 7 | L32: - | M32: - | N32: - | O32: - | P32: 0 | Q32: 4 | R32: - | S32: 1 | T32: 1 | U32: - | V32: 5 | W32: 4 | X32: 31 | Y32: - | AA32: 2 | AB32: - | AC32: - | AD32: - | AE32: =SUM(B32:AD32) -> 120
A33: Painter | B33: - | C33: 38 | D33: 13 | E33: 27 | G33: - | H33: - | I33: - | J33: - | K33: 0 | L33: 18 | M33: - | N33: - | O33: - | P33: 0 | Q33: 9 | R33: 11 | S33: - | T33: - | U33: 0 | V33: 31 | W33: - | X33: - | Y33: - | Z33: - | AA33: - | AB33: - | AC33: - | AD33: - | AE33: =SUM(B33:AD33) -> 147
A34: Scaffolder | B34: - | C34: 3 | D34: - | E34: 4 | F34: - | H34: - | I34: - | J34: - | K34: - | L34: - | M34: - | N34: - | O34: - | P34: - | Q34: - | R34: - | S34: - | T34: - | U34: - | V34: - | W34: - | X34: - | Y34: - | Z34: - | AA34: - | AB34: - | AC34: - | AD34: - | AE34: =SUM(B34:AD34) -> 7
A35: Electrician | B35: - | C35: 1 | D35: - | E35: 1 | F35: - | G35: - | H35: - | I35: - | J35: - | K35: - | L35: - | M35: - | N35: - | O35: - | P35: - | Q35: - | R35: - | S35: - | T35: - | U35: - | V35: - | W35: - | X35: - | Y35: - | Z35: - | AA35: - | AB35: - | AC35: - | AD35: - | AE35: =SUM(B35:AD35) -> 2
A36: Rigger | B36: - | C36: - | E36: - | F36: 1 | G36: - | H36: - | I36: - | J36: - | K36: - | L36: - | M36: - | N36: - | O36: - | P36: - | Q36: - | R36: - | S36: - | T36: - | U36: - | V36: - | W36: - | X36: - | Y36: - | Z36: - | AA36: - | AB36: - | AC36: - | AD36: - | AE36: =SUM(B36:AD36) -> 1
A37: Helper - Surveyor Asst. | B37: - | C37: - | D37: - | E37: 2 | F37: - | G37: - | H37: - | I37: - | J37: - | K37: - | L37: - | M37: - | N37: - | O37: - | P37: - | Q37: - | R37: - | S37: - | T37: - | U37: - | V37: - | W37: - | X37: - | Y37: - | Z37: - | AA37: - | AB37: - | AC37: - | AD37: - | AE37: =SUM(B37:AD37) -> 2
A38: Office Boy | B38: 1 | C38: - | D38: - | E38: - | F38: - | G38: - | H38: - | I38: - | J38: - | K38: - | L38: - | M38: - | N38: - | O38: - | P38: - | Q38: - | R38: - | S38: - | T38: - | U38: - | V38: - | W38: - | X38: - | Y38: - | Z38: - | AA38: - | AB38: - | AC38: - | AD38: - | AE38: =SUM(B38:AD38) -> 1
A39: Asst. Storekeeper | B39: - | C39: 2 | D39: - | E39: 2 | F39: - | G39: - | H39: - | I39: - | J39: - | K39: - | L39: - | M39: - | N39: - | O39: - | P39: - | Q39: - | R39: - | S39: - | T39: - | U39: - | V39: - | W39: - | X39: - | Y39: - | AA39: - | AB39: - | AC39: - | AD39: - | AE39: =SUM(B39:AD39) -> 4
A40: Helper | B40: - | C40: 29 | D40: 4 | E40: 5 | F40: 2 | G40: - | H40: 0 | I40: 15 | J40: - | K40: 13 | L40: - | M40: - | N40: - | O40: 6 | P40: 5 | Q40: 12 | R40: 20 | S40: - | T40: - | U40: - | V40: - | W40: - | X40: 26 | Y40: - | AA40: - | AB40: - | AC40: - | AD40: - | AE40: =SUM(B40:AD40) -> 137
...

Sheet Summary
A1: 46011
A2: Direct Manpoer
A3: Position | B3: Villa | C3: B3 | D3: B2 | E3: Laydown
A4: Gypsum - Team Leader | B4: 1 | C4: 4 | D4: 0 | E4: 0
A5: Mason - Tiler Tiler Leader | B5: 1 | C5: 0 | D5: 2 | E5: -
A6: Gypsum Installer | B6: ='Summary SI, Rental & Subcon'!C31+'Summary SI, Rental & Subcon'!L31+'Summary SI, Rental & Subcon'!O31+'Summary SI, Rental & Subcon'!Q31+'Summary SI, Rental & Subcon'!S31+'Summary SI, Rental & Subcon'!T31 -> 72 | C6: ='Summary SI, Rental & Subcon'!E31+'Summary SI, Rental & Subcon'!R31+'Summary SI, Rental & Subcon'!V31 -> 52 | D6: 5 | E6: 4
A7: Mason - Tiler/Mason | B7: ='Summary SI, Rental & Subcon'!C32+'Summary SI, Rental & Subcon'!I32+'Summary SI, Rental & Subcon'!Q32+'Summary SI, Rental & Subcon'!S32+'Summary SI, Rental & Subcon'!T32 -> 28 | C7: ='Summary SI, Rental & Subcon'!E32+'Summary SI, Rental & Subcon'!K32+'Summary SI, Rental & Subcon'!V32+'Summary SI, Rental & Subcon'!W32+'Summary SI, Rental & Subcon'!X32+'Summary SI, Rental & Subcon'!AA32 -> 67 | D7: ='Summary SI, Rental & Subcon'!D32 -> 24 | E7: 1
A8: Painter | B8: ='Summary SI, Rental & Subcon'!C33+'Summary SI, Rental & Subcon'!L33+'Summary SI, Rental & Subcon'!Q33 -> 65 | C8: ='Summary SI, Rental & Subcon'!E33+'Summary SI, Rental & Subcon'!R33+'Summary SI, Rental & Subcon'!V33 -> 69 | D8: ='Summary SI, Rental & Subcon'!D33 -> 13 | E8: 0
A9: Scaffolder | B9: 3 | C9: 4 | D9: - | E9: -
A10: Electrician | B10: 1 | C10: 1 | D10: - | E10: -
A11: Rigger | D11: - | E11: 1
A12: Helper - Surveyor Asst. | B12: 1 | C12: 1 | D12: - | E12: -
A13: Asst. Storekeeper | B13: 2 | C13: 2 | D13: - | E13: -
A14: Helper | B14: ='Summary SI, Rental & Subcon'!C40+'Summary SI, Rental & Subcon'!I40+'Summary SI, Rental & Subcon'!O40+'Summary SI, Rental & Subcon'!Q40 -> 62 | C14: ='Summary SI, Rental & Subcon'!E40+'Summary SI, Rental & Subcon'!K40+'Summary SI, Rental & Subcon'!R40+'Summary SI, Rental & Subcon'!X40 -> 64 | D14: ='Summary SI, Rental & Subcon'!D40+'Summary SI, Rental & Subcon'!P40 -> 9 | E14: 2
A15: Carpenter | B15: ='Summary SI, Rental & Subcon'!C41+'Summary SI, Rental & Subcon'!O41 -> 16 | C15: ='Summary SI, Rental & Subcon'!E41+'Summary SI, Rental & Subcon'!M41 -> 31 | D15: ='Summary SI, Rental & Subcon'!D41+'Summary SI, Rental & Subcon'!N41 -> 17 | E15: -
A16: Welder | B16: - | C16: 5 | D16: - | E16: -
A17: Gateman | B17: - | C17: 1 | D17: - | E17: -
A18: Polishing | B18: 13 | C18: 4 | D18: - | E18: -
A19: Glass Fabricator | B19: - | C19: - | D19: - | E19: -
C20: Total | E20: =SUM(Table35[[Villa]:[Laydown]]) -> 648
