Workbook
Name FX_Rate_USDtoSAR: #REF!
Name FX_Rate_USDtoSAR: #REF!

Sheet JAN25 RXX-XXX-CXX Summary
A1: Report Data Date | B1: Program Code | C1: Program Name | D1: Asset Code | E1: Asset Code | F1: Package ID | G1: Contract ID | H1: Package Name As per Contract | I1: Vendor Name As per Contract | J1: Vendor Type | K1: Project Start Date | L1: Project Finish Date | M1: Category | N1: Type | O1: Trade | P1: Job Title | Q1: =IF(_xlfn.XLOOKUP($A$2,LISTS!$L$2:$L$106,LISTS!M2:M106)="","N/A",_xlfn.XLOOKUP($A$2,LISTS!$L$2:$L$106,LISTS!M2:M106)) -> 45927 | R1: =IF(_xlfn.XLOOKUP($A$2,LISTS!$L$2:$L$106,LISTS!N2:N106)="","N/A",_xlfn.XLOOKUP($A$2,LISTS!$L$2:$L$106,LISTS!N2:N106)) -> 45928 | S1: =IF(_xlfn.XLOOKUP($A$2,LISTS!$L$2:$L$106,LISTS!O2:O106)="","N/A",_xlfn.XLOOKUP($A$2,LISTS!$L$2:$L$106,LISTS!O2:O106)) -> 45929 | T1: =IF(_xlfn.XLOOKUP($A$2,LISTS!$L$2:$L$106,LISTS!P2:P106)="","N/A",_xlfn.XLOOKUP($A$2,LISTS!$L$2:$L$106,LISTS!P2:P106)) -> 45930 | U1: =IF(_xlfn.XLOOKUP($A$2,LISTS!$L$2:$L$106,LISTS!Q2:Q106)="","N/A",_xlfn.XLOOKUP($A$2,LISTS!$L$2:$L$106,LISTS!Q2:Q106)) -> 45931 | V1: =IF(_xlfn.XLOOKUP($A$2,LISTS!$L$2:$L$106,LISTS!R2:R106)="","N/A",_xlfn.XLOOKUP($A$2,LISTS!$L$2:$L$106,LISTS!R2:R106)) -> 45932 | W1: =IF(_xlfn.XLOOKUP($A$2,LISTS!$L$2:$L$106,LISTS!S2:S106)="","N/A",_xlfn.XLOOKUP($A$2,LISTS!$L$2:$L$106,LISTS!S2:S106)) -> 45933 | X1: =IF(_xlfn.XLOOKUP($A$2,LISTS!$L$2:$L$106,LISTS!T2:T106)="","N/A",_xlfn.XLOOKUP($A$2,LISTS!$L$2:$L$106,LISTS!T2:T106)) -> 45934 | ... AY1: =IF(_xlfn.XLOOKUP($A$2,LISTS!$L$2:$L$106,LISTS!AU2:AU106)="","N/A",_xlfn.XLOOKUP($A$2,LISTS!$L$2:$L$106,LISTS!AU2:AU106)) -> 45961
A2: 45961 | B2: 2 | C2: =IFERROR(_xlfn.XLOOKUP(B2,LISTS!A2:A15,LISTS!B2:B15),"") -> Triple Bay Central | D2: 1.TB.02.012.02 | E2: =IFERROR(_xlfn.XLOOKUP(D2,LISTS!D2:D145,LISTS!E2:E145),"") -> Four Seasons Resort Branded Residences | F2: C05 | G2: =D2&F2 -> 1.TB.02.012.02C05 | H2: Fit-Out | I2: Saudi Icon | J2: Contractor | K2: 45469 | L2: 45799 | M2: Staff | N2: Office | O2: General | P2: Project Director | Q2: ='01'!I11 -> 1 | R2: ='02'!I11 -> 1 | S2: ='03'!I11 -> 1 | T2: ='04'!I11 -> 1 | U2: ='05'!I11 -> 1 | V2: ='06'!I11 -> 1 | W2: ='07'!I11 -> 0 | X2: ='08'!I11 -> 1 | Y2: ='09'!I11 -> 1 | Z2: ='10'!I11 -> 1 | AA2: ='11'!I11 -> 1 | AB2: ='12'!I11 -> 1 | AC2: ='13'!I11 -> 1 | AD2: ='14'!I11 -> 0 | AE2: ='15'!I11 -> 1 | AF2: ='16'!I11 -> 1 | AG2: ='17'!I11 -> 1 | AH2: ='18'!I11 -> 1 | AI2: ='19'!I11 -> 1 | AJ2: ='20'!I11 -> 1 | AK2: ='21'!I11 -> 0 | AL2: ='22'!I11 -> 1 | AM2: ='23'!I11 -> 1 | AN2: ='24'!I11 -> 1 | AO2: ='25'!I11 -> 1 | AP2: ='26'!I11 -> 1 | AQ2: ='27'!I11 -> 1 | AR2: ='28'!I11 -> 0 | AS2: ='29'!I11 -> 1 | AT2: ='30'!I11 -> 1 | AU2: ='31'!I11 -> 1 | AV2: ='32'!I11 -> 1 | AW2: ='33'!I11 -> 1 | AX2: ='34'!I11 -> 1 | AY2: ='35'!I11 -> 0
A3: =A2 -> 45961 | B3: =B2 -> 2 | C3: =C2 -> Triple Bay Central | D3: =D2 -> 1.TB.02.012.02 | E3: =E2 -> Four Seasons Resort Branded Residences | F3: =F2 -> C05 | G3: =G2 -> 1.TB.02.012.02C05 | H3: =H2 -> Fit-Out | I3: =IF(I2="","",I2) -> Saudi Icon | J3: =IF(J2="","",J2) -> Contractor | K3: =IF(K2="","",K2) -> 45469 | L3: =IF(L2="","",L2) -> 45799 | M3: Staff | N3: Office | O3: General | P3: Project Manager | Q3: ='01'!I12 -> 1 | R3: ='02'!I12 -> 1 | S3: ='03'!I12 -> 1 | T3: ='04'!I12 -> 1 | U3: ='05'!I12 -> 1 | V3: ='06'!I12 -> 1 | W3: ='07'!I12 -> 0 | X3: ='08'!I12 -> 1 | Y3: ='09'!I12 -> 1 | Z3: ='10'!I12 -> 1 | AA3: ='11'!I12 -> 1 | AB3: ='12'!I12 -> 1 | AC3: ='13'!I12 -> 1 | AD3: ='14'!I12 -> 0 | AE3: ='15'!I12 -> 1 | AF3: ='16'!I12 -> 1 | AG3: ='17'!I12 -> 1 | AH3: ='18'!I12 -> 1 | AI3: ='19'!I12 -> 1 | AJ3: ='20'!I12 -> 1 | AK3: ='21'!I12 -> 0 | AL3: ='22'!I12 -> 1 | AM3: ='23'!I12 -> 1 | AN3: ='24'!I12 -> 1 | AO3: ='25'!I12 -> 1 | AP3: ='26'!I12 -> 1 | AQ3: ='27'!I12 -> 1 | AR3: ='28'!I12 -> 0 | AS3: ='29'!I12 -> 1 | AT3: ='30'!I12 -> 1 | AU3: ='31'!I12 -> 1 | AV3: ='32'!I12 -> 1 | AW3: ='33'!I12 -> 1 | AX3: ='34'!I12 -> 1 | AY3: ='35'!I12 -> 0
A4: =A3 -> 45961 | B4: =B3 -> 2 | C4: =C3 -> Triple Bay Central | D4: =D3 -> 1.TB.02.012.02 | E4: =E3 -> Four Seasons Resort Branded Residences | F4: =F3 -> C05 | G4: =G3 -> 1.TB.02.012.02C05 | H4: =H3 -> Fit-Out | I4: =I3 -> Saudi Icon | J4: =IF(J3="","",J3) -> Contractor | K4: =$K$3 -> 45469 | L4: =$L$3 -> 45799 | M4: Staff | N4: Office | O4: General | P4: Facility Manager | Q4: ='01'!I13 -> 0 | R4: ='02'!I13 -> 0 | S4: ='03'!I13 -> 0 | T4: ='04'!I13 -> 0 | U4: ='05'!I13 -> 0 | V4: ='06'!I13 -> 0 | W4: ='07'!I13 -> 0 | X4: ='08'!I13 -> 0 | Y4: ='09'!I13 -> 0 | Z4: ='10'!I13 -> 0 | AA4: ='11'!I13 -> 0 | AB4: ='12'!I13 -> 0 | AC4: ='13'!I13 -> 0 | AD4: ='14'!I13 -> 0 | AE4: ='15'!I13 -> 0 | AF4: ='16'!I13 -> 0 | AG4: ='17'!I13 -> 0 | AH4: ='18'!I13 -> 0 | AI4: ='19'!I13 -> 0 | AJ4: ='20'!I13 -> 0 | AK4: ='21'!I13 -> 0 | AL4: ='22'!I13 -> 0 | AM4: ='23'!I13 -> 0 | AN4: ='24'!I13 -> 0 | AO4: ='25'!I13 -> 0 | AP4: ='26'!I13 -> 0 | AQ4: ='27'!I13 -> 0 | AR4: ='28'!I13 -> 0 | AS4: ='29'!I13 -> 0 | AT4: ='30'!I13 -> 0 | AU4: ='31'!I13 -> 0 | AV4: ='32'!I13 -> 0 | AW4: ='33'!I13 -> 0 | AX4: ='34'!I13 -> 0 | AY4: ='35'!I13 -> 0
A5: =A4 -> 45961 | B5: =B4 -> 2 | C5: =C4 -> Triple Bay Central | D5: =D4 -> 1.TB.02.012.02 | E5: =E4 -> Four Seasons Resort Branded Residences | F5: =F4 -> C05 | G5: =G4 -> 1.TB.02.012.02C05 | H5: =H4 -> Fit-Out | I5: =I4 -> Saudi Icon | J5: =IF(J4="","",J4) -> Contractor | K5: =$K$3 -> 45469 | L5: =$L$3 -> 45799 | M5: Staff | N5: Office | O5: General | P5: Technical Manager | Q5: ='01'!I14 -> 0 | R5: ='02'!I14 -> 0 | S5: ='03'!I14 -> 0 | T5: ='04'!I14 -> 0 | U5: ='05'!I14 -> 0 | V5: ='06'!I14 -> 0 | W5: ='07'!I14 -> 0 | X5: ='08'!I14 -> 0 | Y5: ='09'!I14 -> 0 | Z5: ='10'!I14 -> 0 | AA5: ='11'!I14 -> 0 | AB5: ='12'!I14 -> 0 | AC5: ='13'!I14 -> 0 | AD5: ='14'!I14 -> 0 | AE5: ='15'!I14 -> 0 | AF5: ='16'!I14 -> 0 | AG5: ='17'!I14 -> 0 | AH5: ='18'!I14 -> 0 | AI5: ='19'!I14 -> 0 | AJ5: ='20'!I14 -> 0 | AK5: ='21'!I14 -> 0 | AL5: ='22'!I14 -> 0 | AM5: ='23'!I14 -> 0 | AN5: ='24'!I14 -> 0 | AO5: ='25'!I14 -> 0 | AP5: ='26'!I14 -> 0 | AQ5: ='27'!I14 -> 0 | AR5: ='28'!I14 -> 0 | AS5: ='29'!I14 -> 0 | AT5: ='30'!I14 -> 0 | AU5: ='31'!I14 -> 0 | AV5: ='32'!I14 -> 0 | AW5: ='33'!I14 -> 0 | AX5: ='34'!I14 -> 0 | AY5: ='35'!I14 -> 0
A6: =A5 -> 45961 | B6: =B5 -> 2 | C6: =C5 -> Triple Bay Central | D6: =D5 -> 1.TB.02.012.02 | E6: =E5 -> Four Seasons Resort Branded Residences | F6: =F5 -> C05 | G6: =G5 -> 1.TB.02.012.02C05 | H6: =H5 -> Fit-Out | I6: =I5 -> Saudi Icon | J6: =IF(J5="","",J5) -> Contractor | K6: =$K$3 -> 45469 | L6: =$L$3 -> 45799 | M6: Staff | N6: Office | O6: General | P6: Architect | Q6: ='01'!I15 -> 0 | R6: ='02'!I15 -> 0 | S6: ='03'!I15 -> 0 | T6: ='04'!I15 -> 0 | U6: ='05'!I15 -> 0 | V6: ='06'!I15 -> 0 | W6: ='07'!I15 -> 0 | X6: ='08'!I15 -> 0 | Y6: ='09'!I15 -> 0 | Z6: ='10'!I15 -> 0 | AA6: ='11'!I15 -> 0 | AB6: ='12'!I15 -> 0 | AC6: ='13'!I15 -> 0 | AD6: ='14'!I15 -> 0 | AE6: ='15'!I15 -> 0 | AF6: ='16'!I15 -> 0 | AG6: ='17'!I15 -> 0 | AH6: ='18'!I15 -> 0 | AI6: ='19'!I15 -> 0 | AJ6: ='20'!I15 -> 0 | AK6: ='21'!I15 -> 0 | AL6: ='22'!I15 -> 0 | AM6: ='23'!I15 -> 0 | AN6: ='24'!I15 -> 0 | AO6: ='25'!I15 -> 0 | AP6: ='26'!I15 -> 0 | AQ6: ='27'!I15 -> 0 | AR6: ='28'!I15 -> 0 | AS6: ='29'!I15 -> 0 | AT6: ='30'!I15 -> 0 | AU6: ='31'!I15 -> 0 | AV6: ='32'!I15 -> 0 | AW6: ='33'!I15 -> 0 | AX6: ='34'!I15 -> 0 | AY6: ='35'!I15 -> 0
A7: =A6 -> 45961 | B7: =B6 -> 2 | C7: =C6 -> Triple Bay Central | D7: =D6 -> 1.TB.02.012.02 | E7: =E6 -> Four Seasons Resort Branded Residences | F7: =F6 -> C05 | G7: =G6 -> 1.TB.02.012.02C05 | H7: =H6 -> Fit-Out | I7: =I6 -> Saudi Icon | J7: =IF(J6="","",J6) -> Contractor | K7: =$K$3 -> 45469 | L7: =$L$3 -> 45799 | M7: Staff | N7: Office | O7: General | P7: Technical Engineer | Q7: ='01'!I16 -> 0 | R7: ='02'!I16 -> 0 | S7: ='03'!I16 -> 0 | T7: ='04'!I16 -> 0 | U7: ='05'!I16 -> 0 | V7: ='06'!I16 -> 0 | W7: ='07'!I16 -> 0 | X7: ='08'!I16 -> 0 | Y7: ='09'!I16 -> 0 | Z7: ='10'!I16 -> 0 | AA7: ='11'!I16 -> 0 | AB7: ='12'!I16 -> 0 | AC7: ='13'!I16 -> 0 | AD7: ='14'!I16 -> 0 | AE7: ='15'!I16 -> 0 | AF7: ='16'!I16 -> 0 | AG7: ='17'!I16 -> 0 | AH7: ='18'!I16 -> 0 | AI7: ='19'!I16 -> 0 | AJ7: ='20'!I16 -> 0 | AK7: ='21'!I16 -> 0 | AL7: ='22'!I16 -> 0 | AM7: ='23'!I16 -> 0 | AN7: ='24'!I16 -> 0 | AO7: ='25'!I16 -> 0 | AP7: ='26'!I16 -> 0 | AQ7: ='27'!I16 -> 0 | AR7: ='28'!I16 -> 0 | AS7: ='29'!I16 -> 0 | AT7: ='30'!I16 -> 0 | AU7: ='31'!I16 -> 0 | AV7: ='32'!I16 -> 0 | AW7: ='33'!I16 -> 0 | AX7: ='34'!I16 -> 0 | AY7: ='35'!I16 -> 0
A8: =A7 -> 45961 | B8: =B7 -> 2 | C8: =C7 -> Triple Bay Central | D8: =D7 -> 1.TB.02.012.02 | E8: =E7 -> Four Seasons Resort Branded Residences | F8: =F7 -> C05 | G8: =G7 -> 1.TB.02.012.02C05 | H8: =H7 -> Fit-Out | I8: =I7 -> Saudi Icon | J8: =IF(J7="","",J7) -> Contractor | K8: =$K$3 -> 45469 | L8: =$L$3 -> 45799 | M8: Staff | N8: Office | O8: General | P8: Draftsman | Q8: ='01'!I17 -> 0 | R8: ='02'!I17 -> 0 | S8: ='03'!I17 -> 0 | T8: ='04'!I17 -> 0 | U8: ='05'!I17 -> 0 | V8: ='06'!I17 -> 0 | W8: ='07'!I17 -> 0 | X8: ='08'!I17 -> 0 | Y8: ='09'!I17 -> 0 | Z8: ='10'!I17 -> 0 | AA8: ='11'!I17 -> 0 | AB8: ='12'!I17 -> 0 | AC8: ='13'!I17 -> 0 | AD8: ='14'!I17 -> 0 | AE8: ='15'!I17 -> 0 | AF8: ='16'!I17 -> 0 | AG8: ='17'!I17 -> 0 | AH8: ='18'!I17 -> 0 | AI8: ='19'!I17 -> 0 | AJ8: ='20'!I17 -> 0 | AK8: ='21'!I17 -> 0 | AL8: ='22'!I17 -> 0 | AM8: ='23'!I17 -> 0 | AN8: ='24'!I17 -> 0 | AO8: ='25'!I17 -> 0 | AP8: ='26'!I17 -> 0 | AQ8: ='27'!I17 -> 0 | AR8: ='28'!I17 -> 0 | AS8: ='29'!I17 -> 0 | AT8: ='30'!I17 -> 0 | AU8: ='31'!I17 -> 0 | AV8: ='32'!I17 -> 0 | AW8: ='33'!I17 -> 0 | AX8: ='34'!I17 -> 0 | AY8: ='35'!I17 -> 0
A9: =A8 -> 45961 | B9: =B8 -> 2 | C9: =C8 -> Triple Bay Central | D9: =D8 -> 1.TB.02.012.02 | E9: =E8 -> Four Seasons Resort Branded Residences | F9: =F8 -> C05 | G9: =G8 -> 1.TB.02.012.02C05 | H9: =H8 -> Fit-Out | I9: =I8 -> Saudi Icon | J9: =IF(J8="","",J8) -> Contractor | K9: =$K$3 -> 45469 | L9: =$L$3 -> 45799 | M9: Staff | N9: Office | O9: General | P9: Controls Manager | Q9: ='01'!I18 -> 0 | R9: ='02'!I18 -> 0 | S9: ='03'!I18 -> 0 | T9: ='04'!I18 -> 0 | U9: ='05'!I18 -> 0 | V9: ='06'!I18 -> 0 | W9: ='07'!I18 -> 0 | X9: ='08'!I18 -> 0 | Y9: ='09'!I18 -> 0 | Z9: ='10'!I18 -> 0 | AA9: ='11'!I18 -> 0 | AB9: ='12'!I18 -> 0 | AC9: ='13'!I18 -> 0 | AD9: ='14'!I18 -> 0 | AE9: ='15'!I18 -> 0 | AF9: ='16'!I18 -> 0 | AG9: ='17'!I18 -> 0 | AH9: ='18'!I18 -> 2 | AI9: ='19'!I18 -> 0 | AJ9: ='20'!I18 -> 0 | AK9: ='21'!I18 -> 0 | AL9: ='22'!I18 -> 0 | AM9: ='23'!I18 -> 0 | AN9: ='24'!I18 -> 0 | AO9: ='25'!I18 -> 0 | AP9: ='26'!I18 -> 0 | AQ9: ='27'!I18 -> 0 | AR9: ='28'!I18 -> 0 | AS9: ='29'!I18 -> 0 | AT9: ='30'!I18 -> 0 | AU9: ='31'!I18 -> 0 | AV9: ='32'!I18 -> 0 | AW9: ='33'!I18 -> 0 | AX9: ='34'!I18 -> 0 | AY9: ='35'!I18 -> 0
A10: =A9 -> 45961 | B10: =B9 -> 2 | C10: =C9 -> Triple Bay Central | D10: =D9 -> 1.TB.02.012.02 | E10: =E9 -> Four Seasons Resort Branded Residences | F10: =F9 -> C05 | G10: =G9 -> 1.TB.02.012.02C05 | H10: =H9 -> Fit-Out | I10: =I9 -> Saudi Icon | J10: =IF(J9="","",J9) -> Contractor | K10: =$K$3 -> 45469 | L10: =$L$3 -> 45799 | M10: Staff | N10: Office | O10: General | P10: Controls Engineer | Q10: ='01'!I19 -> 0 | R10: ='02'!I19 -> 0 | S10: ='03'!I19 -> 0 | T10: ='04'!I19 -> 0 | U10: ='05'!I19 -> 0 | V10: ='06'!I19 -> 0 | W10: ='07'!I19 -> 0 | X10: ='08'!I19 -> 0 | Y10: ='09'!I19 -> 0 | Z10: ='10'!I19 -> 0 | AA10: ='11'!I19 -> 0 | AB10: ='12'!I19 -> 0 | AC10: ='13'!I19 -> 0 | AD10: ='14'!I19 -> 0 | AE10: ='15'!I19 -> 0 | AF10: ='16'!I19 -> 0 | AG10: ='17'!I19 -> 0 | AH10: ='18'!I19 -> 0 | AI10: ='19'!I19 -> 0 | AJ10: ='20'!I19 -> 0 | AK10: ='21'!I19 -> 0 | AL10: ='22'!I19 -> 0 | AM10: ='23'!I19 -> 0 | AN10: ='24'!I19 -> 0 | AO10: ='25'!I19 -> 0 | AP10: ='26'!I19 -> 0 | AQ10: ='27'!I19 -> 0 | AR10: ='28'!I19 -> 0 | AS10: ='29'!I19 -> 0 | AT10: ='30'!I19 -> 0 | AU10: ='31'!I19 -> 0 | AV10: ='32'!I19 -> 0 | AW10: ='33'!I19 -> 0 | AX10: ='34'!I19 -> 0 | AY10: ='35'!I19 -> 0
A11: =A10 -> 45961 | B11: =B10 -> 2 | C11: =C10 -> Triple Bay Central | D11: =D10 -> 1.TB.02.012.02 | E11: =E10 -> Four Seasons Resort Branded Residences | F11: =F10 -> C05 | G11: =G10 -> 1.TB.02.012.02C05 | H11: =H10 -> Fit-Out | I11: =I10 -> Saudi Icon | J11: =IF(J10="","",J10) -> Contractor | K11: =$K$3 -> 45469 | L11: =$L$3 -> 45799 | M11: Staff | N11: Office | O11: General | P11: Document Controller | Q11: ='01'!I20 -> 1 | R11: ='02'!I20 -> 2 | S11: ='03'!I20 -> 2 | T11: ='04'!I20 -> 2 | U11: ='05'!I20 -> 2 | V11: ='06'!I20 -> 2 | W11: ='07'!I20 -> 0 | X11: ='08'!I20 -> 2 | Y11: ='09'!I20 -> 2 | Z11: ='10'!I20 -> 2 | AA11: ='11'!I20 -> 2 | AB11: ='12'!I20 -> 2 | AC11: ='13'!I20 -> 1 | AD11: ='14'!I20 -> 0 | AE11: ='15'!I20 -> 1 | AF11: ='16'!I20 -> 1 | AG11: ='17'!I20 -> 2 | AH11: ='18'!I20 -> 0 | AI11: ='19'!I20 -> 2 | AJ11: ='20'!I20 -> 2 | AK11: ='21'!I20 -> 0 | AL11: ='22'!I20 -> 2 | AM11: ='23'!I20 -> 2 | AN11: ='24'!I20 -> 2 | AO11: ='25'!I20 -> 2 | AP11: ='26'!I20 -> 2 | AQ11: ='27'!I20 -> 2 | AR11: ='28'!I20 -> 0 | AS11: ='29'!I20 -> 2 | AT11: ='30'!I20 -> 2 | AU11: ='31'!I20 -> 2 | AV11: ='32'!I20 -> 2 | AW11: ='33'!I20 -> 2 | AX11: ='34'!I20 -> 2 | AY11: ='35'!I20 -> 0
A12: =A11 -> 45961 | B12: =B11 -> 2 | C12: =C11 -> Triple Bay Central | D12: =D11 -> 1.TB.02.012.02 | E12: =E11 -> Four Seasons Resort Branded Residences | F12: =F11 -> C05 | G12: =G11 -> 1.TB.02.012.02C05 | H12: =H11 -> Fit-Out | I12: =I11 -> Saudi Icon | J12: =IF(J11="","",J11) -> Contractor | K12: =$K$3 -> 45469 | L12: =$L$3 -> 45799 | M12: Staff | N12: Office | O12: General | P12: Contracts Manager | Q12: ='01'!I21 -> 0 | R12: ='02'!I21 -> 0 | S12: ='03'!I21 -> 0 | T12: ='04'!I21 -> 0 | U12: ='05'!I21 -> 0 | V12: ='06'!I21 -> 0 | W12: ='07'!I21 -> 0 | X12: ='08'!I21 -> 0 | Y12: ='09'!I21 -> 0 | Z12: ='10'!I21 -> 0 | AA12: ='11'!I21 -> 0 | AB12: ='12'!I21 -> 0 | AC12: ='13'!I21 -> 0 | AD12: ='14'!I21 -> 0 | AE12: ='15'!I21 -> 0 | AF12: ='16'!I21 -> 0 | AG12: ='17'!I21 -> 0 | AH12: ='18'!I21 -> 0 | AI12: ='19'!I21 -> 0 | AJ12: ='20'!I21 -> 0 | AK12: ='21'!I21 -> 0 | AL12: ='22'!I21 -> 0 | AM12: ='23'!I21 -> 0 | AN12: ='24'!I21 -> 0 | AO12: ='25'!I21 -> 0 | AP12: ='26'!I21 -> 0 | AQ12: ='27'!I21 -> 0 | AR12: ='28'!I21 -> 0 | AS12: ='29'!I21 -> 0 | AT12: ='30'!I21 -> 0 | AU12: ='31'!I21 -> 0 | AV12: ='32'!I21 -> 0 | AW12: ='33'!I21 -> 0 | AX12: ='34'!I21 -> 0 | AY12: ='35'!I21 -> 0
A13: =A12 -> 45961 | B13: =B12 -> 2 | C13: =C12 -> Triple Bay Central | D13: =D12 -> 1.TB.02.012.02 | E13: =E12 -> Four Seasons Resort Branded Residences | F13: =F12 -> C05 | G13: =G12 -> 1.TB.02.012.02C05 | H13: =H12 -> Fit-Out | I13: =I12 -> Saudi Icon | J13: =IF(J12="","",J12) -> Contractor | K13: =$K$3 -> 45469 | L13: =$L$3 -> 45799 | M13: Staff | N13: Office | O13: General | P13: Contract Administrator | Q13: ='01'!I22 -> 0 | R13: ='02'!I22 -> 0 | S13: ='03'!I22 -> 0 | T13: ='04'!I22 -> 0 | U13: ='05'!I22 -> 0 | V13: ='06'!I22 -> 0 | W13: ='07'!I22 -> 0 | X13: ='08'!I22 -> 0 | Y13: ='09'!I22 -> 0 | Z13: ='10'!I22 -> 0 | AA13: ='11'!I22 -> 0 | AB13: ='12'!I22 -> 0 | AC13: ='13'!I22 -> 0 | AD13: ='14'!I22 -> 0 | AE13: ='15'!I22 -> 0 | AF13: ='16'!I22 -> 0 | AG13: ='17'!I22 -> 0 | AH13: ='18'!I22 -> 0 | AI13: ='19'!I22 -> 0 | AJ13: ='20'!I22 -> 0 | AK13: ='21'!I22 -> 0 | AL13: ='22'!I22 -> 0 | AM13: ='23'!I22 -> 0 | AN13: ='24'!I22 -> 0 | AO13: ='25'!I22 -> 0 | AP13: ='26'!I22 -> 0 | AQ13: ='27'!I22 -> 0 | AR13: ='28'!I22 -> 0 | AS13: ='29'!I22 -> 0 | AT13: ='30'!I22 -> 0 | AU13: ='31'!I22 -> 0 | AV13: ='32'!I22 -> 0 | AW13: ='33'!I22 -> 0 | AX13: ='34'!I22 -> 0 | AY13: ='35'!I22 -> 0
A14: =A13 -> 45961 | B14: =B13 -> 2 | C14: =C13 -> Triple Bay Central | D14: =D13 -> 1.TB.02.012.02 | E14: =E13 -> Four Seasons Resort Branded Residences | F14: =F13 -> C05 | G14: =G13 -> 1.TB.02.012.02C05 | H14: =H13 -> Fit-Out | I14: =I13 -> Saudi Icon | J14: =IF(J13="","",J13) -> Contractor | K14: =$K$3 -> 45469 | L14: =$L$3 -> 45799 | M14: Staff | N14: Office | O14: General | P14: Accounts Manager | Q14: ='01'!I23 -> 0 | R14: ='02'!I23 -> 0 | S14: ='03'!I23 -> 0 | T14: ='04'!I23 -> 0 | U14: ='05'!I23 -> 0 | V14: ='06'!I23 -> 0 | W14: ='07'!I23 -> 0 | X14: ='08'!I23 -> 0 | Y14: ='09'!I23 -> 0 | Z14: ='10'!I23 -> 0 | AA14: ='11'!I23 -> 0 | AB14: ='12'!I23 -> 0 | AC14: ='13'!I23 -> 0 | AD14: ='14'!I23 -> 0 | AE14: ='15'!I23 -> 0 | AF14: ='16'!I23 -> 0 | AG14: ='17'!I23 -> 0 | AH14: ='18'!I23 -> 0 | AI14: ='19'!I23 -> 0 | AJ14: ='20'!I23 -> 0 | AK14: ='21'!I23 -> 0 | AL14: ='22'!I23 -> 0 | AM14: ='23'!I23 -> 0 | AN14: ='24'!I23 -> 0 | AO14: ='25'!I23 -> 0 | AP14: ='26'!I23 -> 0 | AQ14: ='27'!I23 -> 0 | AR14: ='28'!I23 -> 0 | AS14: ='29'!I23 -> 0 | AT14: ='30'!I23 -> 0 | AU14: ='31'!I23 -> 0 | AV14: ='32'!I23 -> 0 | AW14: ='33'!I23 -> 0 | AX14: ='34'!I23 -> 0 | AY14: ='35'!I23 -> 0
A15: =A14 -> 45961 | B15: =B14 -> 2 | C15: =C14 -> Triple Bay Central | D15: =D14 -> 1.TB.02.012.02 | E15: =E14 -> Four Seasons Resort Branded Residences | F15: =F14 -> C05 | G15: =G14 -> 1.TB.02.012.02C05 | H15: =H14 -> Fit-Out | I15: =I14 -> Saudi Icon | J15: =IF(J14="","",J14) -> Contractor | K15: =$K$3 -> 45469 | L15: =$L$3 -> 45799 | M15: Staff | N15: Office | O15: General | P15: Accountant | Q15: ='01'!I24 -> 0 | R15: ='02'!I24 -> 0 | S15: ='03'!I24 -> 0 | T15: ='04'!I24 -> 0 | U15: ='05'!I24 -> 0 | V15: ='06'!I24 -> 0 | W15: ='07'!I24 -> 0 | X15: ='08'!I24 -> 0 | Y15: ='09'!I24 -> 0 | Z15: ='10'!I24 -> 0 | AA15: ='11'!I24 -> 0 | AB15: ='12'!I24 -> 0 | AC15: ='13'!I24 -> 0 | AD15: ='14'!I24 -> 0 | AE15: ='15'!I24 -> 0 | AF15: ='16'!I24 -> 0 | AG15: ='17'!I24 -> 0 | AH15: ='18'!I24 -> 0 | AI15: ='19'!I24 -> 0 | AJ15: ='20'!I24 -> 0 | AK15: ='21'!I24 -> 0 | AL15: ='22'!I24 -> 0 | AM15: ='23'!I24 -> 0 | AN15: ='24'!I24 -> 0 | AO15: ='25'!I24 -> 0 | AP15: ='26'!I24 -> 0 | AQ15: ='27'!I24 -> 0 | AR15: ='28'!I24 -> 0 | AS15: ='29'!I24 -> 0 | AT15: ='30'!I24 -> 0 | AU15: ='31'!I24 -> 0 | AV15: ='32'!I24 -> 0 | AW15: ='33'!I24 -> 0 | AX15: ='34'!I24 -> 0 | AY15: ='35'!I24 -> 0
... A74: =A73 -> 45961 | B74: =B73 -> 2 | C74: =C73 -> Triple Bay Central | D74: =D73 -> 1.TB.02.012.02 | E74: =E73 -> Four Seasons Resort Branded Residences | F74: =F73 -> C05 | G74: =G73 -> 1.TB.02.012.02C05 | H74: =H73 -> Fit-Out | I74: =I73 -> Saudi Icon | J74: =IF(J73="","",J73) -> Contractor | K74: =$K$3 -> 45469 | L74: =$L$3 -> 45799 | M74: Labour | N74: Unskilled | O74: General | P74: Watchman | Q74: ='01'!I83 -> 0 | R74: ='02'!I83 -> 0 | S74: ='03'!I83 -> 0 | T74: ='04'!I83 -> 0 | U74: ='05'!I83 -> 0 | V74: ='06'!I83 -> 0 | W74: ='07'!I83 -> 0 | X74: ='08'!I83 -> 0 | Y74: ='09'!I83 -> 0 | Z74: ='10'!I83 -> 0 | AA74: ='11'!I83 -> 0 | AB74: ='12'!I83 -> 0 | AC74: ='13'!I83 -> 0 | AD74: ='14'!I83 -> 0 | AE74: ='15'!I83 -> 0 | AF74: ='16'!I83 -> 0 | AG74: ='17'!I83 -> 0 | AH74: ='18'!I83 -> 0 | AI74: ='19'!I83 -> 0 | AJ74: ='20'!I83 -> 0 | AK74: ='21'!I83 -> 0 | AL74: ='22'!I83 -> 0 | AM74: ='23'!I83 -> 0 | AN74: ='24'!I83 -> 0 | AO74: ='25'!I83 -> 0 | AP74: ='26'!I83 -> 0 | AQ74: ='27'!I83 -> 0 | AR74: ='28'!I83 -> 0 | AS74: ='29'!I83 -> 0 | AT74: ='30'!I83 -> 0 | AU74: ='31'!I83 -> 0 | AV74: ='32'!I83 -> 0 | AW74: ='33'!I83 -> 0 | AX74: ='34'!I83 -> 0 | AY74: ='35'!I83 -> 0

Sheet LISTS
A1: Program Code | B1: Program Name | D1: Asset Code | E1: Asset Name | G1: Package ID | I1: Vendor Type | L1: Reporting Date | M1: D1 | N1: D2 | O1: D3 | P1: D4 | Q1: D5 | R1: D6 | S1: D7 | T1: D8 | U1: D9 | V1: D10 | W1: D11 | X1: D12 | Y1: D13 | Z1: D14 | AA1: D15 | AB1: D16 | AC1: D17 | AD1: D18 | AE1: D19 | AF1: D20 | AG1: D21 | AH1: D22 | AI1: D23 | AJ1: D24 | AK1: D25 | AL1: D26 | AM1: D27 | AN1: D28 | AO1: D29 | AP1: D30 | AQ1: D31 | AR1: D32 | AS1: D33 | AT1: D34 | AU1: D35
A2: 1 | B2: Marina Village | D2: 1.TB.01.002.02 | E2: Marina Village Apartments | G2: B01 | I2: Contractor | K2: 1 | L2: 45296 | M2: 45290 | N2: =M2+1 -> 45291 | O2: =N2+1 -> 45292 | P2: =O2+1 -> 45293 | Q2: =P2+1 -> 45294 | R2: =Q2+1 -> 45295 | S2: =R2+1 -> 45296 | T2: =S2+1 -> 45297 | U2: =T2+1 -> 45298 | ... AU2: =AT2+1 -> 45324
A3: 2 | B3: Triple Bay Central | D3: 1.TB.01.002.03 | E3: Marina Lifestyle Hotel | G3: B02 | I3: Consultant | K3: 2 | L3: 45303 | M3: 45290 | N3: =M3+1 -> 45291 | O3: =N3+1 -> 45292 | P3: =O3+1 -> 45293 | Q3: =P3+1 -> 45294 | R3: =Q3+1 -> 45295 | S3: =R3+1 -> 45296 | T3: =S3+1 -> 45297 | U3: =T3+1 -> 45298 | ... AU3: =AT3+1 -> 45324
A4: 3 | B4: Wellness Core | D4: 1.TB.01.002.01 | E4: Marina Village Retail & F&B | G4: B03 | K4: 3 | L4: 45310 | M4: 45290 | N4: =M4+1 -> 45291 | O4: =N4+1 -> 45292 | P4: =O4+1 -> 45293 | Q4: =P4+1 -> 45294 | R4: =Q4+1 -> 45295 | S4: =R4+1 -> 45296 | T4: =S4+1 -> 45297 | U4: =T4+1 -> 45298 | ... AU4: =AT4+1 -> 45324
A5: 4 | B5: Triple Bay - Wide | D5: 1.TB.01.003.01 | E5: AMAALA Yacht Club | G5: B04 | K5: 4 | L5: 45317 | M5: 45290 | N5: =M5+1 -> 45291 | O5: =N5+1 -> 45292 | P5: =O5+1 -> 45293 | Q5: =P5+1 -> 45294 | R5: =Q5+1 -> 45295 | S5: =R5+1 -> 45296 | T5: =S5+1 -> 45297 | U5: =T5+1 -> 45298 | ... AU5: =AT5+1 -> 45324
A6: 5 | B6: Ocean Golf | D6: 1.TB.01.005.01 | E6: Red Sea Marine Life Institute | G6: B05 | K6: 5 | L6: 45324 | M6: =M5 -> 45290 | N6: =M6+1 -> 45291 | O6: =N6+1 -> 45292 | P6: =O6+1 -> 45293 | Q6: =P6+1 -> 45294 | R6: =Q6+1 -> 45295 | S6: =R6+1 -> 45296 | T6: =S6+1 -> 45297 | U6: =T6+1 -> 45298 | ... AU6: =AT6+1 -> 45324
A7: 6 | B7: Triple Bay East | D7: 1.TB.01.006.01 | E7: Village Boutique Branded Condos | G7: B06 | K7: 6 | L7: 45331 | M7: =$AU$6+1 -> 45325 | N7: =M7+1 -> 45326 | O7: =N7+1 -> 45327 | P7: =O7+1 -> 45328 | Q7: =P7+1 -> 45329 | R7: =Q7+1 -> 45330 | S7: =R7+1 -> 45331 | T7: =S7+1 -> 45332 | U7: =T7+1 -> 45333 | ... AN7: =AM7+1 -> 45352
A8: 7 | B8: Triple Bay South | D8: 1.TB.01.006.02 | E8: Marina Village Private Villas | G8: B07 | K8: 7 | L8: 45338 | M8: =$AU$6+1 -> 45325 | N8: =M8+1 -> 45326 | O8: =N8+1 -> 45327 | P8: =O8+1 -> 45328 | Q8: =P8+1 -> 45329 | R8: =Q8+1 -> 45330 | S8: =R8+1 -> 45331 | T8: =S8+1 -> 45332 | U8: =T8+1 -> 45333 | ... AN8: =AM8+1 -> 45352
A9: 8 | B9: Construction Village | D9: 1.TB.01.006.03 | E9: Village Boutique Hotel | G9: B08 | K9: 8 | L9: 45345 | M9: =$AU$6+1 -> 45325 | N9: =M9+1 -> 45326 | O9: =N9+1 -> 45327 | P9: =O9+1 -> 45328 | Q9: =P9+1 -> 45329 | R9: =Q9+1 -> 45330 | S9: =R9+1 -> 45331 | T9: =S9+1 -> 45332 | U9: =T9+1 -> 45333 | ... AN9: =AM9+1 -> 45352
A10: 9 | B10: Civic Assets | D10: 1.TB.01.009.01 | E10: Marina Hotel 3 | G10: B09 | K10: 9 | L10: 45352 | M10: =$AU$6+1 -> 45325 | N10: =M10+1 -> 45326 | O10: =N10+1 -> 45327 | P10: =O10+1 -> 45328 | Q10: =P10+1 -> 45329 | R10: =Q10+1 -> 45330 | S10: =R10+1 -> 45331 | T10: =S10+1 -> 45332 | U10: =T10+1 -> 45333 | ... AN10: =AM10+1 -> 45352
A11: 10 | B11: Staff Village | D11: 1.TB.01.001.01 | E11: Floating Diving Club | G11: B10 | K11: 10 | L11: 45359 | M11: =$AN$10+1 -> 45353 | N11: =M11+1 -> 45354 | O11: =N11+1 -> 45355 | P11: =O11+1 -> 45356 | Q11: =P11+1 -> 45357 | R11: =Q11+1 -> 45358 | S11: =R11+1 -> 45359 | T11: =S11+1 -> 45360 | U11: =T11+1 -> 45361 | ... AN11: =AM11+1 -> 45380
A12: 11 | B12: PPP | D12: 1.TB.01.031.01 | E12: The Marina | G12: B11 | K12: 11 | L12: 45366 | M12: =$AN$10+1 -> 45353 | N12: =M12+1 -> 45354 | O12: =N12+1 -> 45355 | P12: =O12+1 -> 45356 | Q12: =P12+1 -> 45357 | R12: =Q12+1 -> 45358 | S12: =R12+1 -> 45359 | T12: =S12+1 -> 45360 | U12: =T12+1 -> 45361 | ... AN12: =AM12+1 -> 45380
A13: 12 | B13: Regional Infrastructure | D13: 2.TB.07.I18 | E13: Marine Service Yard & Dry Stack | G13: B12 | K13: 12 | L13: 45373 | M13: =$AN$10+1 -> 45353 | N13: =M13+1 -> 45354 | O13: =N13+1 -> 45355 | P13: =O13+1 -> 45356 | Q13: =P13+1 -> 45357 | R13: =Q13+1 -> 45358 | S13: =R13+1 -> 45359 | T13: =S13+1 -> 45360 | U13: =T13+1 -> 45361 | ... AN13: =AM13+1 -> 45380
A14: 16 | B14: Airport | D14: 1.TB.02.011.01 | E14: Rosewood Resort | G14: B13 | K14: 13 | L14: 45380 | M14: =$AN$10+1 -> 45353 | N14: =M14+1 -> 45354 | O14: =N14+1 -> 45355 | P14: =O14+1 -> 45356 | Q14: =P14+1 -> 45357 | R14: =Q14+1 -> 45358 | S14: =R14+1 -> 45359 | T14: =S14+1 -> 45360 | U14: =T14+1 -> 45361 | ... AN14: =AM14+1 -> 45380
D15: 1.TB.02.011.02 | E15: Rosewood Resort Branded Residences | G15: B14 | K15: 14 | L15: 45387 | M15: =$AN$14+1 -> 45381 | N15: =M15+1 -> 45382 | O15: =N15+1 -> 45383 | P15: =O15+1 -> 45384 | Q15: =P15+1 -> 45385 | R15: =Q15+1 -> 45386 | S15: =R15+1 -> 45387 | T15: =S15+1 -> 45388 | U15: =T15+1 -> 45389 | ... AN15: =AM15+1 -> 45408
D16: 1.TB.02.012.01 | E16: Four Seasons Resort | G16: B15 | K16: 15 | L16: 45394 | M16: =$AN$14+1 -> 45381 | N16: =M16+1 -> 45382 | O16: =N16+1 -> 45383 | P16: =O16+1 -> 45384 | Q16: =P16+1 -> 45385 | R16: =Q16+1 -> 45386 | S16: =R16+1 -> 45387 | T16: =S16+1 -> 45388 | U16: =T16+1 -> 45389 | ... AN16: =AM16+1 -> 45408
D17: 1.TB.02.012.02 | E17: Four Seasons Resort Branded Residences | G17: B16 | K17: 16 | L17: 45401 | M17: =$AN$14+1 -> 45381 | N17: =M17+1 -> 45382 | O17: =N17+1 -> 45383 | P17: =O17+1 -> 45384 | Q17: =P17+1 -> 45385 | R17: =Q17+1 -> 45386 | S17: =R17+1 -> 45387 | T17: =S17+1 -> 45388 | U17: =T17+1 -> 45389 | ... AN17: =AM17+1 -> 45408
D18: 1.TB.02.017.01 | E18: Six Senses Resort | G18: B17 | K18: 17 | L18: 45408 | M18: =$AN$14+1 -> 45381 | N18: =M18+1 -> 45382 | O18: =N18+1 -> 45383 | P18: =O18+1 -> 45384 | Q18: =P18+1 -> 45385 | R18: =Q18+1 -> 45386 | S18: =R18+1 -> 45387 | T18: =S18+1 -> 45388 | U18: =T18+1 -> 45389 | ... AN18: =AM18+1 -> 45408
D19: 1.TB.02.017.02 | E19: Six Senses Resort Branded Residences | G19: B18 | K19: 18 | L19: 45415 | M19: =$AN$18+1 -> 45409 | N19: =M19+1 -> 45410 | O19: =N19+1 -> 45411 | P19: =O19+1 -> 45412 | Q19: =P19+1 -> 45413 | R19: =Q19+1 -> 45414 | S19: =R19+1 -> 45415 | T19: =S19+1 -> 45416 | U19: =T19+1 -> 45417 | ... AU19: =AT19+1 -> 45443
D20: 1.TB.02.018.01 | E20: Farm Residences | G20: B19 | K20: 19 | L20: 45422 | M20: =$AN$18+1 -> 45409 | N20: =M20+1 -> 45410 | O20: =N20+1 -> 45411 | P20: =O20+1 -> 45412 | Q20: =P20+1 -> 45413 | R20: =Q20+1 -> 45414 | S20: =R20+1 -> 45415 | T20: =S20+1 -> 45416 | U20: =T20+1 -> 45417 | ... AU20: =AT20+1 -> 45443
D21: 1.TB.02.018.02 | E21: Organic Farm | G21: B20 | K21: 20 | L21: 45429 | M21: =$AN$18+1 -> 45409 | N21: =M21+1 -> 45410 | O21: =N21+1 -> 45411 | P21: =O21+1 -> 45412 | Q21: =P21+1 -> 45413 | R21: =Q21+1 -> 45414 | S21: =R21+1 -> 45415 | T21: =S21+1 -> 45416 | U21: =T21+1 -> 45417 | ... AU21: =AT21+1 -> 45443
D22: 1.TB.02.018.03 | E22: Organic Gastronomy Centre | G22: B21 | K22: 21 | L22: 45436 | M22: =$AN$18+1 -> 45409 | N22: =M22+1 -> 45410 | O22: =N22+1 -> 45411 | P22: =O22+1 -> 45412 | Q22: =P22+1 -> 45413 | R22: =Q22+1 -> 45414 | S22: =R22+1 -> 45415 | T22: =S22+1 -> 45416 | U22: =T22+1 -> 45417 | ... AU22: =AT22+1 -> 45443
D23: 1.TB.03.007.01 | E23: Integrative Wellness Resort | G23: B22 | K23: 22 | L23: 45443 | M23: =$AN$18+1 -> 45409 | N23: =M23+1 -> 45410 | O23: =N23+1 -> 45411 | P23: =O23+1 -> 45412 | Q23: =P23+1 -> 45413 | R23: =Q23+1 -> 45414 | S23: =R23+1 -> 45415 | T23: =S23+1 -> 45416 | U23: =T23+1 -> 45417 | ... AU23: =AT23+1 -> 45443
D24: 1.TB.03.007.02 | E24: Integrated Resort Branded Residences | G24: B23 | K24: 23 | L24: 45450 | M24: =$AU$23+1 -> 45444 | N24: =M24+1 -> 45445 | O24: =N24+1 -> 45446 | P24: =O24+1 -> 45447 | Q24: =P24+1 -> 45448 | R24: =Q24+1 -> 45449 | S24: =R24+1 -> 45450 | T24: =S24+1 -> 45451 | U24: =T24+1 -> 45452 | ... AN24: =AM24+1 -> 45471
D25: 1.TB.03.007.03 | E25: Integrative Wellness Resort - Family | G25: B24 | K25: 24 | L25: 45457 | M25: =$AU$23+1 -> 45444 | N25: =M25+1 -> 45445 | O25: =N25+1 -> 45446 | P25: =O25+1 -> 45447 | Q25: =P25+1 -> 45448 | R25: =Q25+1 -> 45449 | S25: =R25+1 -> 45450 | T25: =S25+1 -> 45451 | U25: =T25+1 -> 45452 | ... AN25: =AM25+1 -> 45471
D26: 1.TB.03.008.01 | E26: Medical Wellness Resort | G26: B25 | K26: 25 | L26: 45464 | M26: =$AU$23+1 -> 45444 | N26: =M26+1 -> 45445 | O26: =N26+1 -> 45446 | P26: =O26+1 -> 45447 | Q26: =P26+1 -> 45448 | R26: =Q26+1 -> 45449 | S26: =R26+1 -> 45450 | T26: =S26+1 -> 45451 | U26: =T26+1 -> 45452 | ... AN26: =AM26+1 -> 45471
D27: 1.TB.03.008.02 | E27: Medical Wellness Branded Residential | G27: B26 | K27: 26 | L27: 45471 | M27: =$AU$23+1 -> 45444 | N27: =M27+1 -> 45445 | O27: =N27+1 -> 45446 | P27: =O27+1 -> 45447 | Q27: =P27+1 -> 45448 | R27: =Q27+1 -> 45449 | S27: =R27+1 -> 45450 | T27: =S27+1 -> 45451 | U27: =T27+1 -> 45452 | ... AN27: =AM27+1 -> 45471
D28: 1.TB.03.040.01 | E28: Wellness Village Retail | G28: B27 | K28: 27 | L28: 45478 | M28: =$AN$27+1 -> 45472 | N28: =M28+1 -> 45473 | O28: =N28+1 -> 45474 | P28: =O28+1 -> 45475 | Q28: =P28+1 -> 45476 | R28: =Q28+1 -> 45477 | S28: =R28+1 -> 45478 | T28: =S28+1 -> 45479 | U28: =T28+1 -> 45480 | ... AU28: =AT28+1 -> 45506
D29: 1.TB.04.030.01 | E29: Public Realm | G29: B28 | K29: 28 | L29: 45485 | M29: =$AN$27+1 -> 45472 | N29: =M29+1 -> 45473 | O29: =N29+1 -> 45474 | P29: =O29+1 -> 45475 | Q29: =P29+1 -> 45476 | R29: =Q29+1 -> 45477 | S29: =R29+1 -> 45478 | T29: =S29+1 -> 45479 | U29: =T29+1 -> 45480 | ... AU29: =AT29+1 -> 45506
D30: 1.TB.04.030.02 | E30: Landscaping - Linear Park | G30: B29 | K30: 29 | L30: 45492 | M30: =$AN$27+1 -> 45472 | N30: =M30+1 -> 45473 | O30: =N30+1 -> 45474 | P30: =O30+1 -> 45475 | Q30: =P30+1 -> 45476 | R30: =Q30+1 -> 45477 | S30: =R30+1 -> 45478 | T30: =S30+1 -> 45479 | U30: =T30+1 -> 45480 | ... AU30: =AT30+1 -> 45506
D31: 1.TB.04.030.03 | E31: Beaches / Coastal Reserve Improvements | G31: B30 | K31: 30 | L31: 45499 | M31: =$AN$27+1 -> 45472 | N31: =M31+1 -> 45473 | O31: =N31+1 -> 45474 | P31: =O31+1 -> 45475 | Q31: =P31+1 -> 45476 | R31: =Q31+1 -> 45477 | S31: =R31+1 -> 45478 | T31: =S31+1 -> 45479 | U31: =T31+1 -> 45480 | ... AU31: =AT31+1 -> 45506
D32: 1.TB.04.036.01 | E32: Coral Relocation | G32: B31 | K32: 31 | L32: 45506 | M32: =$AN$27+1 -> 45472 | N32: =M32+1 -> 45473 | O32: =N32+1 -> 45474 | P32: =O32+1 -> 45475 | Q32: =P32+1 -> 45476 | R32: =Q32+1 -> 45477 | S32: =R32+1 -> 45478 | T32: =S32+1 -> 45479 | U32: =T32+1 -> 45480 | ... AU32: =AT32+1 -> 45506
D33: 1.TB.04.004.01 | E33: Early Works | G33: B32 | K33: 32 | L33: 45513 | M33: =$AU$32+1 -> 45507 | N33: =M33+1 -> 45508 | O33: =N33+1 -> 45509 | P33: =O33+1 -> 45510 | Q33: =P33+1 -> 45511 | R33: =Q33+1 -> 45512 | S33: =R33+1 -> 45513 | T33: =S33+1 -> 45514 | U33: =T33+1 -> 45515 | ... AN33: =AM33+1 -> 45534
D34: 1.TB.04.029.01 | E34: Primary Infrastructure | G34: B33 | K34: 33 | L34: 45520 | M34: =$AU$32+1 -> 45507 | N34: =M34+1 -> 45508 | O34: =N34+1 -> 45509 | P34: =O34+1 -> 45510 | Q34: =P34+1 -> 45511 | R34: =Q34+1 -> 45512 | S34: =R34+1 -> 45513 | T34: =S34+1 -> 45514 | U34: =T34+1 -> 45515 | ... AN34: =AM34+1 -> 45534
D35: 1.TB.04.029.02 | E35: Micro Data Centre | G35: B34 | K35: 34 | L35: 45527 | M35: =$AU$32+1 -> 45507 | N35: =M35+1 -> 45508 | O35: =N35+1 -> 45509 | P35: =O35+1 -> 45510 | Q35: =P35+1 -> 45511 | R35: =Q35+1 -> 45512 | S35: =R35+1 -> 45513 | T35: =S35+1 -> 45514 | U35: =T35+1 -> 45515 | ... AN35: =AM35+1 -> 45534
D36: 1.TB.04.034.01 | E36: Triple Bay Construction Logistics | G36: B35 | K36: 35 | L36: 45534 | M36: =$AU$32+1 -> 45507 | N36: =M36+1 -> 45508 | O36: =N36+1 -> 45509 | P36: =O36+1 -> 45510 | Q36: =P36+1 -> 45511 | R36: =Q36+1 -> 45512 | S36: =R36+1 -> 45513 | T36: =S36+1 -> 45514 | U36: =T36+1 -> 45515 | ... AN36: =AM36+1 -> 45534
D37: 1.TB.05.014.01 | E37: Wellness Resort 2 | G37: B36 | K37: 36 | L37: 45541 | M37: =$AN$36+1 -> 45535 | N37: =M37+1 -> 45536 | O37: =N37+1 -> 45537 | P37: =O37+1 -> 45538 | Q37: =P37+1 -> 45539 | R37: =Q37+1 -> 45540 | S37: =R37+1 -> 45541 | T37: =S37+1 -> 45542 | U37: =T37+1 -> 45543 | ... AN37: =AM37+1 -> 45562
D38: 1.TB.05.014.02 | E38: Wellness Resort 2 - Branded Residences | G38: B37 | K38: 37 | L38: 45548 | M38: =$AN$36+1 -> 45535 | N38: =M38+1 -> 45536 | O38: =N38+1 -> 45537 | P38: =O38+1 -> 45538 | Q38: =P38+1 -> 45539 | R38: =Q38+1 -> 45540 | S38: =R38+1 -> 45541 | T38: =S38+1 -> 45542 | U38: =T38+1 -> 45543 | ... AN38: =AM38+1 -> 45562
D39: 1.TB.05.021.01 | E39: Beach Club | G39: B38 | K39: 38 | L39: 45555 | M39: =$AN$36+1 -> 45535 | N39: =M39+1 -> 45536 | O39: =N39+1 -> 45537 | P39: =O39+1 -> 45538 | Q39: =P39+1 -> 45539 | R39: =Q39+1 -> 45540 | S39: =R39+1 -> 45541 | T39: =S39+1 -> 45542 | U39: =T39+1 -> 45543 | ... AN39: =AM39+1 -> 45562
D40: 1.TB.05.021.02 | E40: Golf Club House | G40: B39 | K40: 39 | L40: 45562 | M40: =$AN$36+1 -> 45535 | N40: =M40+1 -> 45536 | O40: =N40+1 -> 45537 | P40: =O40+1 -> 45538 | Q40: =P40+1 -> 45539 | R40: =Q40+1 -> 45540 | S40: =R40+1 -> 45541 | T40: =S40+1 -> 45542 | U40: =T40+1 -> 45543 | ... AN40: =AM40+1 -> 45562
...

Sheet User Manual
Q1: Year 2024 Calendar
B2: General Notes
B3: 1 | C3: Laborforce records shall be reported on a weekly basis
B4: 2 | C4: A reporting week starts on Saturday
B5: 3 | C5: The cutoff date of a reporting week is Friday
B6: 4 | C6: Submission of Laborforce records is the following Saturday to the reporting week
B7: 5 | C7: This template is updated to report Laborforce records over the 52 weeks of year 2024
B8: 6 | C8: Monthly timeline doesn't start and end on first and last day of the month, since Laborforce reporting is on a weekly basis
C9: This explains why Tab 01 is not the first day of the month
B10: 7 | C10: Refer to Year2024 Calendar ahead, to know the start and finish date of every reporting week and how many weeks for each reporting month
B11: 8 | C11: The workbook consists of 39 sheets/tabs as follows:
C14: Partially Protected | D14: Summary Tab | E14: To show categorized Laborforce records along the reporting month.
C15: Protected | D15: Manual Tab | E15: The current tab, it shows general guidelines and explains how to fillout this workbook
C16: Unprotected | D16: Tabs 01 To 35 | E16: Every sheet/tab represents the Laborforce records for each day of the reporting month and should be filled by Project Team
E17: For reporting months of 4 weeks, only 28 tabs will be used
E18: For reporting months of 5 weeks, the 35 tabs will be used
C19: Protected & Hidden | D19: LISTS Tab | E19: Contains drop-down lists for report attributes for proper data validtion during data entry process
C20: Partially Protected | D20: GRAPH Tab | E20: Shows monthly Laborforce graph to visually check and validate Laborforce records before submission
B30: How to fillout the sheet
B31: 1 | C31: in Summary Tab, only fillout the Cells in Green as follows:
C32: 1.1 | D32: Select Reporting Data Date (Cut-off date) from the dropdown list at Cell A2
D33: Once the reporting data date is selected the monthly Timeline will automatically get updated from Cell R1 to Cell AZ1
C35: 1.2 | D35: Select Program Code from the dropdown list at Cell B2
C37: 1.3 | D37: Select Asset Code from dropdown list at Cell D2
C39: 1.4 | D39: Select Package ID from dropdown list at Cell F2
C41: 1.5 | D41: Insert Package Name at Cell H2 as mentioned in Contract
C43: 1.6 | D43: Insert Vendor Name at Cell I2 as mentioned in Contract
C45: 1.7 | D45: Select Vendor Type from dropdown list at Cell J2
C47: 1.8 | D47: Insert Project Start Date at Cell K2
C49: 1.9 | D49: Insert Project Finish Date at Cell L2
C51: 1.1 | D51: Rename Summary Tab to reflect reporting month, Program, Asset, Package - DON'T REMOVE WORD SUMMARY
D52: Example: jan24 R01-H13-C01 Summary
C56: All Cells in Green must be filled
B58: 2 | C58: in Tabs 01 till reporting date, fillout the Laborforce count at Columns G & H against their corressponding trade
C59: Note that Absent means not performing at site BUT available at site camp Accomodation including Fridays
B62: 3 | C62: Go to Summary Tab to make sure that all data entered are reflected properly
B65: 4 | C65: Go to Graph Tab to check the trend of the weekly Laborforce records compared to previous week records
C66: Write Justification in case of significant Laborforce decrease
C69: Don't change records of previous weeks, it is useless, records of each individual week are extracted

Sheet GRAPH
B2: Monthly Laborforce Curve
B3: ='JAN25 RXX-XXX-CXX Summary'!G2 -> 1.TB.02.012.02C05 | C3: ='JAN25 RXX-XXX-CXX Summary'!H2 -> Fit-Out
B5: DAY 1 | C5: DAY 2 | D5: Day 3 | E5: DAY 4 | F5: DAY 5 | G5: DAY 6 | H5: DAY 7 | I5: DAY 8 | J5: DAY 9 | K5: DAY 10 | L5: DAY 11 | M5: DAY 12 | N5: DAY 13 | O5: DAY 14 | P5: DAY 15 | Q5: DAY 16 | R5: DAY 17 | S5: DAY 18 | T5: DAY 19 | U5: DAY 20 | V5: DAY 21 | W5: DAY 22 | X5: DAY 23 | Y5: DAY 24 | Z5: DAY 25 | AA5: DAY 26 | AB5: DAY 27 | AC5: DAY 28 | AD5: DAY 29 | AE5: DAY 30 | AF5: DAY 31 | AG5: DAY 32 | AH5: DAY 33 | AI5: DAY 34 | AJ5: DAY 35
B6: ='JAN25 RXX-XXX-CXX Summary'!Q1 -> 45927 | C6: ='JAN25 RXX-XXX-CXX Summary'!R1 -> 45928 | D6: ='JAN25 RXX-XXX-CXX Summary'!S1 -> 45929 | E6: ='JAN25 RXX-XXX-CXX Summary'!T1 -> 45930 | F6: ='JAN25 RXX-XXX-CXX Summary'!U1 -> 45931 | G6: ='JAN25 RXX-XXX-CXX Summary'!V1 -> 45932 | H6: ='JAN25 RXX-XXX-CXX Summary'!W1 -> 45933 | I6: ='JAN25 RXX-XXX-CXX Summary'!X1 -> 45934 | ... AJ6: ='JAN25 RXX-XXX-CXX Summary'!AY1 -> 45961
B7: =SUM('JAN25 RXX-XXX-CXX Summary'!Q2:Q74) -> 637 | C7: =SUM('JAN25 RXX-XXX-CXX Summary'!R2:R74) -> 584 | D7: =SUM('JAN25 RXX-XXX-CXX Summary'!S2:S74) -> 527 | E7: =SUM('JAN25 RXX-XXX-CXX Summary'!T2:T74) -> 542 | F7: =SUM('JAN25 RXX-XXX-CXX Summary'!U2:U74) -> 534 | G7: =SUM('JAN25 RXX-XXX-CXX Summary'!V2:V74) -> 570 | H7: =SUM('JAN25 RXX-XXX-CXX Summary'!W2:W74) -> 35 | I7: =SUM('JAN25 RXX-XXX-CXX Summary'!X2:X74) -> 558 | ... AJ7: =SUM('JAN25 RXX-XXX-CXX Summary'!AY2:AY74) -> 0
B33: NOTES | C33: In case of significatet manpower decrease, please write justification below!

Sheet 01
B2: The Red Sea Development Project
B3: Daily Construction Manpower
B5: Program: | D5: ='JAN25 RXX-XXX-CXX Summary'!$B$2 -> 2 | E5: ='JAN25 RXX-XXX-CXX Summary'!$C$2 -> Triple Bay Central | G5: Report Date: | H5: ='JAN25 RXX-XXX-CXX Summary'!$Q$1 -> 45927
B6: Asset: | D6: ='JAN25 RXX-XXX-CXX Summary'!$D$2 -> 1.TB.02.012.02 | E6: ='JAN25 RXX-XXX-CXX Summary'!$E$2 -> Four Seasons Resort Branded Residences | G6: Report No.
B7: Project/Contract: | D7: ='JAN25 RXX-XXX-CXX Summary'!$G$2 -> 1.TB.02.012.02C05 | E7: ='JAN25 RXX-XXX-CXX Summary'!$H$2 -> Fit-Out | G7: Project Start: | H7: ='JAN25 RXX-XXX-CXX Summary'!$K$2 -> 45469
B8: Contractor Name: | E8: ='JAN25 RXX-XXX-CXX Summary'!$I$2 -> Saudi Icon | G8: Project Finish: | H8: ='JAN25 RXX-XXX-CXX Summary'!$L$2 -> 45799
B10: Category | E10: Job Title / Trade | F10: Remarks | G10: On Site | H10: Absent / Holidays | I10: Total
B11: Staff | C11: Office | D11: General | E11: Project Director | G11: 1 | I11: =SUM(G11:H11) -> 1
B12: Staff | C12: Office | D12: General | E12: Project Manager | G12: 1 | I12: =SUM(G12:H12) -> 1
B13: Staff | C13: Office | D13: General | E13: Facility Manager | I13: =SUM(G13:H13) -> 0
B14: Staff | C14: Office | D14: General | E14: Technical Manager | I14: =SUM(G14:H14) -> 0
B15: Staff | C15: Office | D15: General | E15: Architect | I15: =SUM(G15:H15) -> 0
B16: Staff | C16: Office | D16: General | E16: Technical Engineer | I16: =SUM(G16:H16) -> 0
B17: Staff | C17: Office | D17: General | E17: Draftsman | I17: =SUM(G17:H17) -> 0
B18: Staff | C18: Office | D18: General | E18: Controls Manager | I18: =SUM(G18:H18) -> 0
B19: Staff | C19: Office | D19: General | E19: Controls Engineer | I19: =SUM(G19:H19) -> 0
B20: Staff | C20: Office | D20: General | E20: Document Controller | G20: 1 | I20: =SUM(G20:H20) -> 1
B21: Staff | C21: Office | D21: General | E21: Contracts Manager | I21: =SUM(G21:H21) -> 0
B22: Staff | C22: Office | D22: General | E22: Contract Administrator | I22: =SUM(G22:H22) -> 0
B23: Staff | C23: Office | D23: General | E23: Accounts Manager | I23: =SUM(G23:H23) -> 0
B24: Staff | C24: Office | D24: General | E24: Accountant | I24: =SUM(G24:H24) -> 0
B25: Staff | C25: Office | D25: General | E25: Procurement Manager | I25: =SUM(G25:H25) -> 0
B26: Staff | C26: Office | D26: General | E26: Procurement Eng./Officer | I26: =SUM(G26:H26) -> 0
B27: Staff | C27: Office | D27: General | E27: Stores Manager | I27: =SUM(G27:H27) -> 0
B28: Staff | C28: Office | D28: General | E28: Storekeeper / Timekeeper | G28: 2 | I28: =SUM(G28:H28) -> 2
B29: Staff | C29: Office | D29: General | E29: Safety Manager | G29: 1 | I29: =SUM(G29:H29) -> 1
B30: Staff | C30: Office | D30: General | E30: Safety Officer | G30: 7 | I30: =SUM(G30:H30) -> 7
B31: Staff | C31: Office | D31: General | E31: QS Manager | I31: =SUM(G31:H31) -> 0
B32: Staff | C32: Office | D32: General | E32: Quantity Surveyor | G32: 1 | I32: =SUM(G32:H32) -> 1
B33: Staff | C33: Office | D33: General | E33: Land Surveyor Manager | I33: =SUM(G33:H33) -> 0
B34: Staff | C34: Office | D34: General | E34: Land Surveyor | G34: 3 | I34: =SUM(G34:H34) -> 3
B35: Staff | C35: Office | D35: General | E35: Assistant Surveyor | I35: =SUM(G35:H35) -> 0
B36: Staff | C36: Office | D36: General | E36: HR Administrator | G36: 1 | I36: =SUM(G36:H36) -> 1
B37: Staff | C37: Office | D37: General | E37: IT Support | I37: =SUM(G37:H37) -> 0
B38: Staff | C38: Office | D38: General | E38: Security Manager | I38: =SUM(G38:H38) -> 0
B39: Staff | C39: Office | D39: General | E39: Security Officer | I39: =SUM(G39:H39) -> 0
B40: Staff | C40: Office | D40: General | E40: QA/QC Manager | I40: =SUM(G40:H40) -> 0
B41: Staff | C41: Office | D41: General | E41: QA/QC Officer | G41: 2 | I41: =SUM(G41:H41) -> 2
B42: Staff | C42: Office | D42: General | E42: HSE Manager | I42: =SUM(G42:H42) -> 0
B43: Staff | C43: Office | D43: General | E43: HSE Officer | I43: =SUM(G43:H43) -> 0
...

Sheet 02
B2: The Red Sea Development Project
B3: Daily Construction Manpower
B5: Program: | D5: ='JAN25 RXX-XXX-CXX Summary'!$B$2 -> 2 | E5: ='JAN25 RXX-XXX-CXX Summary'!$C$2 -> Triple Bay Central | G5: Report Date: | H5: ='JAN25 RXX-XXX-CXX Summary'!$R$1 -> 45928
B6: Asset: | D6: ='JAN25 RXX-XXX-CXX Summary'!$D$2 -> 1.TB.02.012.02 | E6: ='JAN25 RXX-XXX-CXX Summary'!$E$2 -> Four Seasons Resort Branded Residences | G6: Report No.
B7: Project/Contract: | D7: ='JAN25 RXX-XXX-CXX Summary'!$G$2 -> 1.TB.02.012.02C05 | E7: ='JAN25 RXX-XXX-CXX Summary'!$H$2 -> Fit-Out | G7: Project Start: | H7: ='JAN25 RXX-XXX-CXX Summary'!$K$2 -> 45469
B8: Contractor Name: | E8: ='JAN25 RXX-XXX-CXX Summary'!$I$2 -> Saudi Icon | G8: Project Finish: | H8: ='JAN25 RXX-XXX-CXX Summary'!$L$2 -> 45799
B10: Category | E10: Job Title / Trade | F10: Remarks | G10: On Site | H10: Absent / Holidays | I10: Total
B11: Staff | C11: Office | D11: General | E11: Project Director | G11: 1 | I11: =SUM(G11:H11) -> 1
B12: Staff | C12: Office | D12: General | E12: Project Manager | G12: 1 | I12: =SUM(G12:H12) -> 1
B13: Staff | C13: Office | D13: General | E13: Facility Manager | I13: =SUM(G13:H13) -> 0
B14: Staff | C14: Office | D14: General | E14: Technical Manager | I14: =SUM(G14:H14) -> 0
B15: Staff | C15: Office | D15: General | E15: Architect | I15: =SUM(G15:H15) -> 0
B16: Staff | C16: Office | D16: General | E16: Technical Engineer | I16: =SUM(G16:H16) -> 0
B17: Staff | C17: Office | D17: General | E17: Draftsman | I17: =SUM(G17:H17) -> 0
B18: Staff | C18: Office | D18: General | E18: Controls Manager | I18: =SUM(G18:H18) -> 0
B19: Staff | C19: Office | D19: General | E19: Controls Engineer | I19: =SUM(G19:H19) -> 0
B20: Staff | C20: Office | D20: General | E20: Document Controller | G20: 2 | I20: =SUM(G20:H20) -> 2
B21: Staff | C21: Office | D21: General | E21: Contracts Manager | I21: =SUM(G21:H21) -> 0
B22: Staff | C22: Office | D22: General | E22: Contract Administrator | I22: =SUM(G22:H22) -> 0
B23: Staff | C23: Office | D23: General | E23: Accounts Manager | I23: =SUM(G23:H23) -> 0
B24: Staff | C24: Office | D24: General | E24: Accountant | I24: =SUM(G24:H24) -> 0
B25: Staff | C25: Office | D25: General | E25: Procurement Manager | I25: =SUM(G25:H25) -> 0
B26: Staff | C26: Office | D26: General | E26: Procurement Eng./Officer | I26: =SUM(G26:H26) -> 0
B27: Staff | C27: Office | D27: General | E27: Stores Manager | I27: =SUM(G27:H27) -> 0
B28: Staff | C28: Office | D28: General | E28: Storekeeper / Timekeeper | G28: 2 | I28: =SUM(G28:H28) -> 2
B29: Staff | C29: Office | D29: General | E29: Safety Manager | G29: 1 | I29: =SUM(G29:H29) -> 1
B30: Staff | C30: Office | D30: General | E30: Safety Officer | G30: 8 | I30: =SUM(G30:H30) -> 8
B31: Staff | C31: Office | D31: General | E31: QS Manager | I31: =SUM(G31:H31) -> 0
B32: Staff | C32: Office | D32: General | E32: Quantity Surveyor | G32: 1 | I32: =SUM(G32:H32) -> 1
B33: Staff | C33: Office | D33: General | E33: Land Surveyor Manager | I33: =SUM(G33:H33) -> 0
B34: Staff | C34: Office | D34: General | E34: Land Surveyor | G34: 3 | I34: =SUM(G34:H34) -> 3
B35: Staff | C35: Office | D35: General | E35: Assistant Surveyor | I35: =SUM(G35:H35) -> 0
B36: Staff | C36: Office | D36: General | E36: HR Administrator | G36: 1 | I36: =SUM(G36:H36) -> 1
B37: Staff | C37: Office | D37: General | E37: IT Support | I37: =SUM(G37:H37) -> 0
B38: Staff | C38: Office | D38: General | E38: Security Manager | I38: =SUM(G38:H38) -> 0
B39: Staff | C39: Office | D39: General | E39: Security Officer | I39: =SUM(G39:H39) -> 0
B40: Staff | C40: Office | D40: General | E40: QA/QC Manager | I40: =SUM(G40:H40) -> 0
B41: Staff | C41: Office | D41: General | E41: QA/QC Officer | G41: 2 | I41: =SUM(G41:H41) -> 2
B42: Staff | C42: Office | D42: General | E42: HSE Manager | I42: =SUM(G42:H42) -> 0
B43: Staff | C43: Office | D43: General | E43: HSE Officer | I43: =SUM(G43:H43) -> 0
...

Sheet 03
B2: The Red Sea Development Project
B3: Daily Construction Manpower
B5: Program: | D5: ='JAN25 RXX-XXX-CXX Summary'!$B$2 -> 2 | E5: ='JAN25 RXX-XXX-CXX Summary'!$C$2 -> Triple Bay Central | G5: Report Date: | H5: ='JAN25 RXX-XXX-CXX Summary'!$S$1 -> 45929
B6: Asset: | D6: ='JAN25 RXX-XXX-CXX Summary'!$D$2 -> 1.TB.02.012.02 | E6: ='JAN25 RXX-XXX-CXX Summary'!$E$2 -> Four Seasons Resort Branded Residences | G6: Report No.
B7: Project/Contract: | D7: ='JAN25 RXX-XXX-CXX Summary'!$G$2 -> 1.TB.02.012.02C05 | E7: ='JAN25 RXX-XXX-CXX Summary'!$H$2 -> Fit-Out | G7: Project Start: | H7: ='JAN25 RXX-XXX-CXX Summary'!$K$2 -> 45469
B8: Contractor Name: | E8: ='JAN25 RXX-XXX-CXX Summary'!$I$2 -> Saudi Icon | G8: Project Finish: | H8: ='JAN25 RXX-XXX-CXX Summary'!$L$2 -> 45799
B10: Category | E10: Job Title / Trade | F10: Remarks | G10: On Site | H10: Absent / Holidays | I10: Total
B11: Staff | C11: Office | D11: General | E11: Project Director | G11: 1 | I11: =SUM(G11:H11) -> 1
B12: Staff | C12: Office | D12: General | E12: Project Manager | G12: 1 | I12: =SUM(G12:H12) -> 1
B13: Staff | C13: Office | D13: General | E13: Facility Manager | I13: =SUM(G13:H13) -> 0
B14: Staff | C14: Office | D14: General | E14: Technical Manager | I14: =SUM(G14:H14) -> 0
B15: Staff | C15: Office | D15: General | E15: Architect | I15: =SUM(G15:H15) -> 0
B16: Staff | C16: Office | D16: General | E16: Technical Engineer | I16: =SUM(G16:H16) -> 0
B17: Staff | C17: Office | D17: General | E17: Draftsman | I17: =SUM(G17:H17) -> 0
B18: Staff | C18: Office | D18: General | E18: Controls Manager | I18: =SUM(G18:H18) -> 0
B19: Staff | C19: Office | D19: General | E19: Controls Engineer | I19: =SUM(G19:H19) -> 0
B20: Staff | C20: Office | D20: General | E20: Document Controller | G20: 2 | I20: =SUM(G20:H20) -> 2
B21: Staff | C21: Office | D21: General | E21: Contracts Manager | I21: =SUM(G21:H21) -> 0
B22: Staff | C22: Office | D22: General | E22: Contract Administrator | I22: =SUM(G22:H22) -> 0
B23: Staff | C23: Office | D23: General | E23: Accounts Manager | I23: =SUM(G23:H23) -> 0
B24: Staff | C24: Office | D24: General | E24: Accountant | I24: =SUM(G24:H24) -> 0
B25: Staff | C25: Office | D25: General | E25: Procurement Manager | I25: =SUM(G25:H25) -> 0
B26: Staff | C26: Office | D26: General | E26: Procurement Eng./Officer | I26: =SUM(G26:H26) -> 0
B27: Staff | C27: Office | D27: General | E27: Stores Manager | I27: =SUM(G27:H27) -> 0
B28: Staff | C28: Office | D28: General | E28: Storekeeper / Timekeeper | G28: 2 | I28: =SUM(G28:H28) -> 2
B29: Staff | C29: Office | D29: General | E29: Safety Manager | G29: 1 | I29: =SUM(G29:H29) -> 1
B30: Staff | C30: Office | D30: General | E30: Safety Officer | G30: 8 | I30: =SUM(G30:H30) -> 8
B31: Staff | C31: Office | D31: General | E31: QS Manager | I31: =SUM(G31:H31) -> 0
B32: Staff | C32: Office | D32: General | E32: Quantity Surveyor | G32: 1 | I32: =SUM(G32:H32) -> 1
B33: Staff | C33: Office | D33: General | E33: Land Surveyor Manager | I33: =SUM(G33:H33) -> 0
B34: Staff | C34: Office | D34: General | E34: Land Surveyor | G34: 3 | I34: =SUM(G34:H34) -> 3
B35: Staff | C35: Office | D35: General | E35: Assistant Surveyor | I35: =SUM(G35:H35) -> 0
B36: Staff | C36: Office | D36: General | E36: HR Administrator | G36: 1 | I36: =SUM(G36:H36) -> 1
B37: Staff | C37: Office | D37: General | E37: IT Support | I37: =SUM(G37:H37) -> 0
B38: Staff | C38: Office | D38: General | E38: Security Manager | I38: =SUM(G38:H38) -> 0
B39: Staff | C39: Office | D39: General | E39: Security Officer | I39: =SUM(G39:H39) -> 0
B40: Staff | C40: Office | D40: General | E40: QA/QC Manager | I40: =SUM(G40:H40) -> 0
B41: Staff | C41: Office | D41: General | E41: QA/QC Officer | G41: 2 | I41: =SUM(G41:H41) -> 2
B42: Staff | C42: Office | D42: General | E42: HSE Manager | I42: =SUM(G42:H42) -> 0
B43: Staff | C43: Office | D43: General | E43: HSE Officer | I43: =SUM(G43:H43) -> 0
...

Sheet 04
B2: The Red Sea Development Project
B3: Daily Construction Manpower
B5: Program: | D5: ='JAN25 RXX-XXX-CXX Summary'!$B$2 -> 2 | E5: ='JAN25 RXX-XXX-CXX Summary'!$C$2 -> Triple Bay Central | G5: Report Date: | H5: ='JAN25 RXX-XXX-CXX Summary'!$T$1 -> 45930
B6: Asset: | D6: ='JAN25 RXX-XXX-CXX Summary'!$D$2 -> 1.TB.02.012.02 | E6: ='JAN25 RXX-XXX-CXX Summary'!$E$2 -> Four Seasons Resort Branded Residences | G6: Report No.
B7: Project/Contract: | D7: ='JAN25 RXX-XXX-CXX Summary'!$G$2 -> 1.TB.02.012.02C05 | E7: ='JAN25 RXX-XXX-CXX Summary'!$H$2 -> Fit-Out | G7: Project Start: | H7: ='JAN25 RXX-XXX-CXX Summary'!$K$2 -> 45469
B8: Contractor Name: | E8: ='JAN25 RXX-XXX-CXX Summary'!$I$2 -> Saudi Icon | G8: Project Finish: | H8: ='JAN25 RXX-XXX-CXX Summary'!$L$2 -> 45799
B10: Category | E10: Job Title / Trade | F10: Remarks | G10: On Site | H10: Absent / Holidays | I10: Total
B11: Staff | C11: Office | D11: General | E11: Project Director | G11: 1 | I11: =SUM(G11:H11) -> 1
B12: Staff | C12: Office | D12: General | E12: Project Manager | G12: 1 | I12: =SUM(G12:H12) -> 1
B13: Staff | C13: Office | D13: General | E13: Facility Manager | I13: =SUM(G13:H13) -> 0
B14: Staff | C14: Office | D14: General | E14: Technical Manager | I14: =SUM(G14:H14) -> 0
B15: Staff | C15: Office | D15: General | E15: Architect | I15: =SUM(G15:H15) -> 0
B16: Staff | C16: Office | D16: General | E16: Technical Engineer | I16: =SUM(G16:H16) -> 0
B17: Staff | C17: Office | D17: General | E17: Draftsman | I17: =SUM(G17:H17) -> 0
B18: Staff | C18: Office | D18: General | E18: Controls Manager | I18: =SUM(G18:H18) -> 0
B19: Staff | C19: Office | D19: General | E19: Controls Engineer | I19: =SUM(G19:H19) -> 0
B20: Staff | C20: Office | D20: General | E20: Document Controller | G20: 2 | I20: =SUM(G20:H20) -> 2
B21: Staff | C21: Office | D21: General | E21: Contracts Manager | I21: =SUM(G21:H21) -> 0
B22: Staff | C22: Office | D22: General | E22: Contract Administrator | I22: =SUM(G22:H22) -> 0
B23: Staff | C23: Office | D23: General | E23: Accounts Manager | I23: =SUM(G23:H23) -> 0
B24: Staff | C24: Office | D24: General | E24: Accountant | I24: =SUM(G24:H24) -> 0
B25: Staff | C25: Office | D25: General | E25: Procurement Manager | I25: =SUM(G25:H25) -> 0
B26: Staff | C26: Office | D26: General | E26: Procurement Eng./Officer | I26: =SUM(G26:H26) -> 0
B27: Staff | C27: Office | D27: General | E27: Stores Manager | I27: =SUM(G27:H27) -> 0
B28: Staff | C28: Office | D28: General | E28: Storekeeper / Timekeeper | G28: 2 | I28: =SUM(G28:H28) -> 2
B29: Staff | C29: Office | D29: General | E29: Safety Manager | G29: 1 | I29: =SUM(G29:H29) -> 1
B30: Staff | C30: Office | D30: General | E30: Safety Officer | G30: 8 | I30: =SUM(G30:H30) -> 8
B31: Staff | C31: Office | D31: General | E31: QS Manager | I31: =SUM(G31:H31) -> 0
B32: Staff | C32: Office | D32: General | E32: Quantity Surveyor | G32: 1 | I32: =SUM(G32:H32) -> 1
B33: Staff | C33: Office | D33: General | E33: Land Surveyor Manager | I33: =SUM(G33:H33) -> 0
B34: Staff | C34: Office | D34: General | E34: Land Surveyor | G34: 3 | I34: =SUM(G34:H34) -> 3
B35: Staff | C35: Office | D35: General | E35: Assistant Surveyor | I35: =SUM(G35:H35) -> 0
B36: Staff | C36: Office | D36: General | E36: HR Administrator | G36: 1 | I36: =SUM(G36:H36) -> 1
B37: Staff | C37: Office | D37: General | E37: IT Support | I37: =SUM(G37:H37) -> 0
B38: Staff | C38: Office | D38: General | E38: Security Manager | I38: =SUM(G38:H38) -> 0
B39: Staff | C39: Office | D39: General | E39: Security Officer | I39: =SUM(G39:H39) -> 0
B40: Staff | C40: Office | D40: General | E40: QA/QC Manager | I40: =SUM(G40:H40) -> 0
B41: Staff | C41: Office | D41: General | E41: QA/QC Officer | G41: 1 | I41: =SUM(G41:H41) -> 1
B42: Staff | C42: Office | D42: General | E42: HSE Manager | I42: =SUM(G42:H42) -> 0
B43: Staff | C43: Office | D43: General | E43: HSE Officer | I43: =SUM(G43:H43) -> 0
...

Sheet 05
B2: The Red Sea Development Project
B3: Daily Construction Manpower
B5: Program: | D5: ='JAN25 RXX-XXX-CXX Summary'!$B$2 -> 2 | E5: ='JAN25 RXX-XXX-CXX Summary'!$C$2 -> Triple Bay Central | G5: Report Date: | H5: ='JAN25 RXX-XXX-CXX Summary'!$U$1 -> 45931
B6: Asset: | D6: ='JAN25 RXX-XXX-CXX Summary'!$D$2 -> 1.TB.02.012.02 | E6: ='JAN25 RXX-XXX-CXX Summary'!$E$2 -> Four Seasons Resort Branded Residences | G6: Report No.
B7: Project/Contract: | D7: ='JAN25 RXX-XXX-CXX Summary'!$G$2 -> 1.TB.02.012.02C05 | E7: ='JAN25 RXX-XXX-CXX Summary'!$H$2 -> Fit-Out | G7: Project Start: | H7: ='JAN25 RXX-XXX-CXX Summary'!$K$2 -> 45469
B8: Contractor Name: | E8: ='JAN25 RXX-XXX-CXX Summary'!$I$2 -> Saudi Icon | G8: Project Finish: | H8: ='JAN25 RXX-XXX-CXX Summary'!$L$2 -> 45799
B10: Category | E10: Job Title / Trade | F10: Remarks | G10: On Site | H10: Absent / Holidays | I10: Total
B11: Staff | C11: Office | D11: General | E11: Project Director | G11: 1 | I11: =SUM(G11:H11) -> 1
B12: Staff | C12: Office | D12: General | E12: Project Manager | G12: 1 | I12: =SUM(G12:H12) -> 1
B13: Staff | C13: Office | D13: General | E13: Facility Manager | I13: =SUM(G13:H13) -> 0
B14: Staff | C14: Office | D14: General | E14: Technical Manager | I14: =SUM(G14:H14) -> 0
B15: Staff | C15: Office | D15: General | E15: Architect | I15: =SUM(G15:H15) -> 0
B16: Staff | C16: Office | D16: General | E16: Technical Engineer | I16: =SUM(G16:H16) -> 0
B17: Staff | C17: Office | D17: General | E17: Draftsman | I17: =SUM(G17:H17) -> 0
B18: Staff | C18: Office | D18: General | E18: Controls Manager | I18: =SUM(G18:H18) -> 0
B19: Staff | C19: Office | D19: General | E19: Controls Engineer | I19: =SUM(G19:H19) -> 0
B20: Staff | C20: Office | D20: General | E20: Document Controller | G20: 2 | I20: =SUM(G20:H20) -> 2
B21: Staff | C21: Office | D21: General | E21: Contracts Manager | I21: =SUM(G21:H21) -> 0
B22: Staff | C22: Office | D22: General | E22: Contract Administrator | I22: =SUM(G22:H22) -> 0
B23: Staff | C23: Office | D23: General | E23: Accounts Manager | I23: =SUM(G23:H23) -> 0
B24: Staff | C24: Office | D24: General | E24: Accountant | I24: =SUM(G24:H24) -> 0
B25: Staff | C25: Office | D25: General | E25: Procurement Manager | I25: =SUM(G25:H25) -> 0
B26: Staff | C26: Office | D26: General | E26: Procurement Eng./Officer | I26: =SUM(G26:H26) -> 0
B27: Staff | C27: Office | D27: General | E27: Stores Manager | I27: =SUM(G27:H27) -> 0
B28: Staff | C28: Office | D28: General | E28: Storekeeper / Timekeeper | G28: 2 | I28: =SUM(G28:H28) -> 2
B29: Staff | C29: Office | D29: General | E29: Safety Manager | G29: 1 | I29: =SUM(G29:H29) -> 1
B30: Staff | C30: Office | D30: General | E30: Safety Officer | G30: 8 | I30: =SUM(G30:H30) -> 8
B31: Staff | C31: Office | D31: General | E31: QS Manager | I31: =SUM(G31:H31) -> 0
B32: Staff | C32: Office | D32: General | E32: Quantity Surveyor | G32: 1 | I32: =SUM(G32:H32) -> 1
B33: Staff | C33: Office | D33: General | E33: Land Surveyor Manager | I33: =SUM(G33:H33) -> 0
B34: Staff | C34: Office | D34: General | E34: Land Surveyor | G34: 2 | I34: =SUM(G34:H34) -> 2
B35: Staff | C35: Office | D35: General | E35: Assistant Surveyor | I35: =SUM(G35:H35) -> 0
B36: Staff | C36: Office | D36: General | E36: HR Administrator | G36: 1 | I36: =SUM(G36:H36) -> 1
B37: Staff | C37: Office | D37: General | E37: IT Support | I37: =SUM(G37:H37) -> 0
B38: Staff | C38: Office | D38: General | E38: Security Manager | I38: =SUM(G38:H38) -> 0
B39: Staff | C39: Office | D39: General | E39: Security Officer | I39: =SUM(G39:H39) -> 0
B40: Staff | C40: Office | D40: General | E40: QA/QC Manager | G40: 1 | I40: =SUM(G40:H40) -> 1
B41: Staff | C41: Office | D41: General | E41: QA/QC Officer | G41: 1 | I41: =SUM(G41:H41) -> 1
B42: Staff | C42: Office | D42: General | E42: HSE Manager | I42: =SUM(G42:H42) -> 0
B43: Staff | C43: Office | D43: General | E43: HSE Officer | I43: =SUM(G43:H43) -> 0
...

Sheet 06
B2: The Red Sea Development Project
B3: Daily Construction Manpower
B5: Program: | D5: ='JAN25 RXX-XXX-CXX Summary'!$B$2 -> 2 | E5: ='JAN25 RXX-XXX-CXX Summary'!$C$2 -> Triple Bay Central | G5: Report Date: | H5: ='JAN25 RXX-XXX-CXX Summary'!$V$1 -> 45932
B6: Asset: | D6: ='JAN25 RXX-XXX-CXX Summary'!$D$2 -> 1.TB.02.012.02 | E6: ='JAN25 RXX-XXX-CXX Summary'!$E$2 -> Four Seasons Resort Branded Residences | G6: Report No.
B7: Project/Contract: | D7: ='JAN25 RXX-XXX-CXX Summary'!$G$2 -> 1.TB.02.012.02C05 | E7: ='JAN25 RXX-XXX-CXX Summary'!$H$2 -> Fit-Out | G7: Project Start: | H7: ='JAN25 RXX-XXX-CXX Summary'!$K$2 -> 45469
B8: Contractor Name: | E8: ='JAN25 RXX-XXX-CXX Summary'!$I$2 -> Saudi Icon | G8: Project Finish: | H8: ='JAN25 RXX-XXX-CXX Summary'!$L$2 -> 45799
B10: Category | E10: Job Title / Trade | F10: Remarks | G10: On Site | H10: Absent / Holidays | I10: Total
B11: Staff | C11: Office | D11: General | E11: Project Director | G11: 1 | I11: =SUM(G11:H11) -> 1
B12: Staff | C12: Office | D12: General | E12: Project Manager | G12: 1 | I12: =SUM(G12:H12) -> 1
B13: Staff | C13: Office | D13: General | E13: Facility Manager | I13: =SUM(G13:H13) -> 0
B14: Staff | C14: Office | D14: General | E14: Technical Manager | I14: =SUM(G14:H14) -> 0
B15: Staff | C15: Office | D15: General | E15: Architect | I15: =SUM(G15:H15) -> 0
B16: Staff | C16: Office | D16: General | E16: Technical Engineer | I16: =SUM(G16:H16) -> 0
B17: Staff | C17: Office | D17: General | E17: Draftsman | I17: =SUM(G17:H17) -> 0
B18: Staff | C18: Office | D18: General | E18: Controls Manager | I18: =SUM(G18:H18) -> 0
B19: Staff | C19: Office | D19: General | E19: Controls Engineer | I19: =SUM(G19:H19) -> 0
B20: Staff | C20: Office | D20: General | E20: Document Controller | G20: 2 | I20: =SUM(G20:H20) -> 2
B21: Staff | C21: Office | D21: General | E21: Contracts Manager | I21: =SUM(G21:H21) -> 0
B22: Staff | C22: Office | D22: General | E22: Contract Administrator | I22: =SUM(G22:H22) -> 0
B23: Staff | C23: Office | D23: General | E23: Accounts Manager | I23: =SUM(G23:H23) -> 0
B24: Staff | C24: Office | D24: General | E24: Accountant | I24: =SUM(G24:H24) -> 0
B25: Staff | C25: Office | D25: General | E25: Procurement Manager | I25: =SUM(G25:H25) -> 0
B26: Staff | C26: Office | D26: General | E26: Procurement Eng./Officer | I26: =SUM(G26:H26) -> 0
B27: Staff | C27: Office | D27: General | E27: Stores Manager | I27: =SUM(G27:H27) -> 0
B28: Staff | C28: Office | D28: General | E28: Storekeeper / Timekeeper | G28: 2 | I28: =SUM(G28:H28) -> 2
B29: Staff | C29: Office | D29: General | E29: Safety Manager | G29: 1 | I29: =SUM(G29:H29) -> 1
B30: Staff | C30: Office | D30: General | E30: Safety Officer | G30: 8 | I30: =SUM(G30:H30) -> 8
B31: Staff | C31: Office | D31: General | E31: QS Manager | I31: =SUM(G31:H31) -> 0
