Workbook

Sheet Attendance
A1: SN | B1: Name | C1: Position | D1: ID | E1: P/A | F1: Location
A2: 1 | B2: Mohammad El Barakeh | C2: Project Director | D2: 2478 | E2: P | F2: Main Office
A3: 2 | B3: Ahmed El Hanash | C3: Project Manager | D3: 1272 | E3: P | F3: Main Office
A4: 3 | B4: Taj Wali | C4: Safety Manager | D4: 2858 | E4: P | F4: Main Office
A5: 4 | B5: Mohammed Abdelnaser | C5: QA/QC Manager | D5: 2691 | E5: P | F5: Main Office
A6: 5 | B6: Inayat | C6: QA/QC Enginner | D6: 3337 | E6: P | F6: Main Office
A7: 6 | B7: Sardar Nayab | C7: QA/QC Enginner | D7: 4585 | E7: P | F7: Main Office
A8: 7 | B8: Shahbaz Ahmad | C8: QA/QC Enginner | D8: 3760 | E8: P | F8: Main Office
A9: 8 | B9: Jan Dastagir | C9: QA/QC Enginner | D9: 3801 | E9: P | F9: Main Office
A10: 9 | B10: Mohammad Fowzan | C10: Q Surveyor Engineer | D10: 2687 | E10: P | F10: Main Office
A11: 10 | B11: Marwan Khalil | C11: Planning Engineer | D11: 4717 | E11: P | F11: Main Office
A12: 11 | B12: Mohammad Shariq | C12: Environmental Engineer | D12: 4797 | E12: P | F12: Main Office
A13: 12 | B13: Kareem Mostafa | C13: Project Engineer | D13: 1835 | E13: P | F13: Main Office
... A35: 34 | B35: Yahdia Raghoua | C35: Site Supervisor | D35: 1435 | E35: P | F35: B3
A36: 35 | B36: Waseem Aftab | C36: General Foreman | D36: 4816 | E36: P | F36: =_xlfn.XLOOKUP(D36,Sheet1!A$2:A$135,Sheet1!B$2:B$135,"Not Found",0) -> B2
A37: 36 | B37: Khalid Halim | C37: General Foreman | D37: 4064 | E37: P | F37: B3
A38: 37 | B38: Shahen Jalal | C38: General Foreman | D38: 2629 | E38: P | F38: =_xlfn.XLOOKUP(D38,Sheet1!A$2:A$135,Sheet1!B$2:B$135,"Not Found",0) -> B3
A39: 38 | B39: Abdelkarim Khari | C39: General Foreman | D39: 4077 | E39: P | F39: B2
A40: 39 | B40: Mahmoud Eid Abdelhady | C40: Painter Foreman | D40: 4510 | E40: P | F40: B3
A41: 40 | B41: Mohammad Wasi | C41: General Foreman | D41: 3004 | E41: P | F41: =_xlfn.XLOOKUP(D41,Sheet1!A$2:A$135,Sheet1!B$2:B$135,"Not Found",0) -> B3
A42: 41 | B42: Imran ahmad | C42: General Foreman | D42: 3005 | E42: P | F42: B3
A43: 42 | B43: Ayman Raafat | C43: General Foreman | D43: 3753 | E43: P | F43: Villa
A44: 43 | B44: Maher Al Asmar | C44: Carpenter Foreman | D44: 3845 | E44: P | F44: Villa
A45: 44 | B45: Adnan Shakeel | C45: Gypsum Team Leader | D45: 4744 | E45: P | F45: =_xlfn.XLOOKUP(D45,Sheet1!A$2:A$135,Sheet1!B$2:B$135,"Not Found",0) -> B3
A46: 45 | B46: Foridul Islam | C46: Gypsum-Team Leader | D46: 2581 | E46: P | F46: =_xlfn.XLOOKUP(D46,Sheet1!A$2:A$135,Sheet1!B$2:B$135,"Not Found",0) -> Villa
A47: 46 | B47: Sohel Rana | C47: Helper/Ass.StoreKeeper | D47: 4091 | E47: P | F47: =_xlfn.XLOOKUP(D47,Sheet1!A$2:A$135,Sheet1!B$2:B$135,"Not Found",0) -> Villa
A48: 47 | B48: Akaeid Abdul | C48: Helper/Ass.StoreKeeper | D48: 2888 | E48: P | F48: =_xlfn.XLOOKUP(D48,Sheet1!A$2:A$135,Sheet1!B$2:B$135,"Not Found",0) -> B2
A49: 48 | B49: Saroj Kumar | C49: Helper/Camp | D49: 2175 | E49: P | F49: CAMP
A50: 49 | B50: Sourav Hasan | C50: Helper/Camp | D50: 4092 | E50: P | F50: CAMP
A51: 50 | B51: Bishnu Prasad | C51: Helper | D51: 3083 | E51: P | F51: =_xlfn.XLOOKUP(D51,Sheet1!A$2:A$135,Sheet1!B$2:B$135,"Not Found",0) -> B3
A52: 51 | B52: Hasib Molla | C52: Helper | D52: 4084 | E52: P | F52: =_xlfn.XLOOKUP(D52,Sheet1!A$2:A$135,Sheet1!B$2:B$135,"Not Found",0) -> LayDown
A53: 52 | B53: Muha Mintu Sarder | C53: Helper | D53: 4090 | E53: P | F53: =_xlfn.XLOOKUP(D53,Sheet1!A$2:A$135,Sheet1!B$2:B$135,"Not Found",0) -> B3
A54: 53 | B54: Suman Miah | C54: Helper | D54: 4093 | E54: P | F54: =_xlfn.XLOOKUP(D54,Sheet1!A$2:A$135,Sheet1!B$2:B$135,"Not Found",0) -> B3
A55: 54 | B55: MD Al Amin | C55: Helper | D55: 4094 | E55: P | F55: =_xlfn.XLOOKUP(D55,Sheet1!A$2:A$135,Sheet1!B$2:B$135,"Not Found",0) -> LayDown
A56: 55 | B56: Kashem Miah | C56: Helper | D56: 2314 | E56: P | F56: =_xlfn.XLOOKUP(D56,Sheet1!A$2:A$135,Sheet1!B$2:B$135,"Not Found",0) -> Villa
A57: 56 | B57: Dilshad Anish | C57: Helper | D57: 2232 | E57: P | F57: =_xlfn.XLOOKUP(D57,Sheet1!A$2:A$135,Sheet1!B$2:B$135,"Not Found",0) -> B2
A58: 57 | B58: Nur Mohammed | C58: Helper | D58: 3206 | E58: P | F58: =_xlfn.XLOOKUP(D58,Sheet1!A$2:A$135,Sheet1!B$2:B$135,"Not Found",0) -> B2
A59: 58 | B59: Mansoor Al Qadhi | C59: Helper | D59: 2462 | E59: P | F59: =_xlfn.XLOOKUP(D59,Sheet1!A$2:A$135,Sheet1!B$2:B$135,"Not Found",0) -> B2
A60: 59 | B60: Ashraf Khan | C60: Helper | D60: 3129 | E60: P | F60: =_xlfn.XLOOKUP(D60,Sheet1!A$2:A$135,Sheet1!B$2:B$135,"Not Found",0) -> B3
A61: 60 | B61: Kaucar Miah | C61: Helper/GypsTeamLeader | D61: 2336 | E61: P | F61: =_xlfn.XLOOKUP(D61,Sheet1!A$2:A$135,Sheet1!B$2:B$135,"Not Found",0) -> B3
...

Sheet Sheet1
A1: 3845 | B1: Villa
A2: 2581 | B2: Villa
A3: 4091 | B3: Villa
A4: 2314 | B4: Villa
A5: 4890 | B5: Villa
A6: 4272 | B6: Villa
A7: 4273 | B7: Villa
A8: 4275 | B8: Villa
A9: 3304 | B9: Villa
A10: 3989 | B10: Villa
A11: 2219 | B11: Villa
A12: 2875 | B12: Villa
... A135: 3240 | B135: LayDown
